Workbook

Sheet output
A1: age_low | B1: age_high | C1: variable | D1: norm_m | E1: norm_sd | F1: norm_n | G1: data_m | H1: data_sd | I1: data_n | J1: t | K1: p | L1: x
A2: 18 | B2: 22 | C2: age | D2: 19.14 | E2: 1.22 | F2: 178 | G2: 21.285714 | H2: 0.75592895 | I2: 7 | J2: 7.1526015 | K2: 0.00015241793 | L2: -6.782054
A3: 18 | B3: 22 | C3: BVMT_t1 | D3: 7.49 | E3: 2.04 | F3: 178 | G3: 9.7142857 | H3: 1.7043362 | I3: 7 | J3: 3.3595582 | K3: 0.012923106 | L3: -2.0695165
A4: 18 | B4: 22 | C4: BVMT_t2 | D4: 10.14 | E4: 1.74 | F4: 178 | G4: 11.428571 | H4: 0.88640526 | I4: 7 | J4: 3.5841542 | K4: 0.0072193945 | L4: -1.6055142
A5: 18 | B5: 22 | C5: BVMT_t3 | D5: 11.1 | E5: 1.16 | F5: 178 | G5: 11.857143 | H5: 0.24397502 | I5: 7 | J5: 5.9739991 | K5: 6.4554659e-06 | L5: -3.4419677
A6: 18 | B6: 22 | C6: BVMT_total_recall | D6: 28.74 | E6: 4.32 | F6: 178 | G6: 33 | H6: 2.5819889 | I6: 7 | J6: 4.1431027 | K6: 0.0038489112 | L6: -2.4066194
A7: 18 | B7: 22 | C7: BVMT_learning | D7: 3.63 | E7: 1.67 | F7: 178 | G7: 2.1428571 | H7: 1.5468863 | I7: 7 | J7: -2.4872063 | K7: 0.043981684 | L7: 1.2109953
A8: 18 | B8: 22 | C8: BVMT_delayed_recall | D8: 10.79 | E8: 1.37 | F8: 178 | G8: 11.857143 | H8: 0.24397502 | I8: 7 | J8: 7.7321512 | K8: 1.7359055e-08 | L8: -6.1432167
A9: 18 | B9: 22 | C9: BVMT_percent_retained | D9: 95.34 | E9: 6.6 | F9: 178 | G9: 100 | H9: 0 | I9: 7 | J9: 9.4200234 | K9: 2.4686153e-17 | L9: -11.923023
A10: 18 | B10: 22 | C10: BVMT_hits | D10: 5.93 | E10: 0.28 | F10: 178 | G10: 5.7142857 | H10: 0.48795004 | I10: 7 | J10: -1.1621408 | K10: 0.28824216 | L10: 0.40296865
A11: 18 | B11: 22 | C11: BVMT_false_alarms | D11: 0.02 | E11: 0.14 | F11: 178 | G11: 0 | H11: 0 | I11: 7 | J11: -1.905952 | K11: 0.058277042 | L11: 0.1793217
A12: 18 | B12: 22 | C12: BVMT_discrimination_index | D12: 5.91 | E12: 0.31 | F12: 178 | G12: 5.7142857 | H12: 0.48795004 | I12: 7 | J12: -1.0528744 | K12: 0.33174098 | L12: 0.29546468
A13: 18 | B13: 22 | C13: BVMT_response_bias | D13: 0.49 | E13: 0.07 | F13: 178 | G13: 0.42857143 | H13: 0.12198751 | I13: 7 | J13: -1.323763 | K13: 0.23261244 | L13: 0.53813283
... A34: 22 | B34: 26 | C34: BVMT_hits | D34: 5.91 | E34: 0.28 | F34: 47 | G34: 5.9090909 | H34: 0.30151134 | I34: 11 | J34: -0.0091217251 | K34: 0.9928479 | L34: 9.979855e-06
A35: 22 | B35: 26 | C35: BVMT_false_alarms | D35: 0 | E35: 0 | F35: 47 | G35: 0 | H35: 0 | I35: 11
A36: 22 | B36: 26 | C36: BVMT_discrimination_index | D36: 5.91 | E36: 0.28 | F36: 47 | G36: 5.9090909 | H36: 0.30151134 | I36: 11 | J36: -0.0091217251 | K36: 0.9928479 | L36: 9.979855e-06
A37: 22 | B37: 26 | C37: BVMT_response_bias | D37: 0.47 | E37: 0.07 | F37: 47 | G37: 0.47727273 | H37: 0.075377836 | I37: 11 | J37: 0.2918952 | K37: 0.77455356 | L37: -0.011366335
A38: 24 | B38: 28 | C38: age | D38: 25.48 | E38: 1.09 | F38: 39 | G38: 26.333333 | H38: 1.4142136 | I38: 9 | J38: 1.6975706 | K38: 0.1195418 | L38: -0.68275403
A39: 24 | B39: 28 | C39: BVMT_t1 | D39: 7.19 | E39: 2.04 | F39: 39 | G39: 9.0555556 | H39: 2.2282903 | I39: 9 | J39: 2.2991195 | K39: 0.041501215 | L39: -1.2430646
A40: 24 | B40: 28 | C40: BVMT_t2 | D40: 9.82 | E40: 1.79 | F40: 39 | G40: 11.111111 | H40: 1.1395662 | I40: 9 | J40: 2.7131936 | K40: 0.01403706 | L40: -1.4113293
A41: 24 | B41: 28 | C41: BVMT_t3 | D41: 10.81 | E41: 1.28 | F41: 39 | G41: 11.833333 | H41: 0.5 | I41: 9 | J41: 3.8737058 | K41: 0.00046303038 | L41: -2.8869871
A42: 24 | B42: 28 | C42: BVMT_total_recall | D42: 27.83 | E42: 4.48 | F42: 39 | G42: 32 | H42: 3.6571847 | I42: 9 | J42: 2.9480923 | K42: 0.010491736 | L42: -1.8980853
A43: 24 | B43: 28 | C43: BVMT_learning | D43: 3.65 | E43: 1.69 | F43: 39 | G43: 2.7777778 | H43: 1.9220938 | I43: 9 | J43: -1.2540848 | K43: 0.23572604 | L43: 0.3159416
A44: 24 | B44: 28 | C44: BVMT_delayed_recall | D44: 10.46 | E44: 1.48 | F44: 39 | G44: 11.722222 | H44: 0.50689688 | I44: 9 | J44: 4.3367017 | K44: 9.9518423e-05 | L44: -3.709807
A45: 24 | B45: 28 | C45: BVMT_percent_retained | D45: 95.08 | E45: 8.04 | F45: 39 | G45: 99.074074 | H45: 1.8373273 | I45: 9 | J45: 2.8015227 | K45: 0.0074183691 | L45: -1.1576827
A46: 24 | B46: 28 | C46: BVMT_hits | D46: 5.89 | E46: 0.3 | F46: 39 | G46: 6 | H46: 0 | I46: 9 | J46: 2.2898326 | K46: 0.027674022 | L46: -0.62850083
A47: 24 | B47: 28 | C47: BVMT_false_alarms | D47: 0 | E47: 0 | F47: 39 | G47: 0 | H47: 0 | I47: 9
A48: 24 | B48: 28 | C48: BVMT_discrimination_index | D48: 5.89 | E48: 0.3 | F48: 39 | G48: 6 | H48: 0 | I48: 9 | J48: 2.2898326 | K48: 0.027674022 | L48: -0.62850083
A49: 24 | B49: 28 | C49: BVMT_response_bias | D49: 0.47 | E49: 0.07 | F49: 39 | G49: 0.5 | H49: 0 | I49: 9 | J49: 2.6764277 | K49: 0.010921857 | L49: -0.9250042
A50: 26 | B50: 30 | C50: age | D50: 28.45 | E50: 1.62 | F50: 42 | G50: 27.6 | H50: 1.5055453 | I50: 10 | J50: -1.5807222 | K50: 0.13564336 | L50: 0.46091256
A51: 26 | B51: 30 | C51: BVMT_t1 | D51: 7.09 | E51: 2.03 | F51: 42 | G51: 8.4 | H51: 2.2705848 | I51: 10 | J51: 1.6722572 | K51: 0.11900669 | L51: -0.58351266
A52: 26 | B52: 30 | C52: BVMT_t2 | D52: 9.72 | E52: 1.8 | F52: 42 | G52: 10.6 | H52: 1.4102797 | I52: 10 | J52: 1.674955 | K52: 0.11247504 | L52: -0.48094336
A53: 26 | B53: 30 | C53: BVMT_t3 | D53: 10.71 | E53: 1.32 | F53: 42 | G53: 11.85 | H53: 0.47434165 | I53: 10 | J53: 4.5067487 | K53: 5.2523137e-05 | L53: -4.0249689
A54: 26 | B54: 30 | C54: BVMT_total_recall | D54: 27.52 | E54: 4.54 | F54: 42 | G54: 30.85 | H54: 3.4322814 | I54: 10 | J54: 2.5777515 | K54: 0.019313784 | L54: -1.3087613
A55: 26 | B55: 30 | C55: BVMT_learning | D55: 3.66 | E55: 1.7 | F55: 42 | G55: 3.45 | H55: 2.060879 | I55: 10 | J55: -0.29892466 | K55: 0.77007652 | L55: 0.013459075
A56: 26 | B56: 30 | C56: BVMT_delayed_recall | D56: 10.35 | E56: 1.52 | F56: 42 | G56: 11.7 | H56: 0.48304589 | I56: 10 | J56: 4.8231866 | K56: 1.6064265e-05 | L56: -4.6508519
A57: 26 | B57: 30 | C57: BVMT_percent_retained | D57: 96.67 | E57: 6.31 | F57: 42 | G57: 98.75 | H57: 2.0126912 | I57: 10 | J57: 1.7881304 | K57: 0.080401023 | L57: -0.3941315
A58: 26 | B58: 30 | C58: BVMT_hits | D58: 5.97 | E58: 0.15 | F58: 42 | G58: 5.9 | H58: 0.31622777 | I58: 10 | J58: -0.68197122 | K58: 0.51076779 | L58: 0.10697926
A59: 26 | B59: 30 | C59: BVMT_false_alarms | D59: 0 | E59: 0 | F59: 42 | G59: 0 | H59: 0 | I59: 10
A60: 26 | B60: 30 | C60: BVMT_discrimination_index | D60: 5.97 | E60: 0.15 | F60: 42 | G60: 5.9 | H60: 0.31622777 | I60: 10 | J60: -0.68197122 | K60: 0.51076779 | L60: 0.10697926
...

Sheet Sheet1
A1: age_low | B1: age_high | C1: variable | D1: x
A2: 18 | B2: 22 | C2: age | D2: -6.782054
A3: 18 | B3: 22 | C3: BVMT_t1 | D3: -2.0695165
A4: 18 | B4: 22 | C4: BVMT_t2 | D4: -1.6055142
A5: 18 | B5: 22 | C5: BVMT_t3 | D5: -3.4419677
A6: 18 | B6: 22 | C6: BVMT_total_recall | D6: -2.4066194
A7: 18 | B7: 22 | C7: BVMT_learning | D7: 1.2109953
A8: 18 | B8: 22 | C8: BVMT_delayed_recall | D8: -6.1432167
A9: 18 | B9: 22 | C9: BVMT_percent_retained | D9: -11.923023
A10: 18 | B10: 22 | C10: BVMT_hits | D10: 0.40296865
A11: 18 | B11: 22 | C11: BVMT_false_alarms | D11: 0.1793217
A12: 18 | B12: 22 | C12: BVMT_discrimination_index | D12: 0.29546468
A13: 18 | B13: 22 | C13: BVMT_response_bias | D13: 0.53813283
... A34: 22 | B34: 26 | C34: BVMT_hits | D34: 9.979855e-06
A35: 22 | B35: 26 | C35: BVMT_false_alarms
A36: 22 | B36: 26 | C36: BVMT_discrimination_index | D36: 9.979855e-06
A37: 22 | B37: 26 | C37: BVMT_response_bias | D37: -0.011366335
A38: 24 | B38: 28 | C38: age | D38: -0.68275403
A39: 24 | B39: 28 | C39: BVMT_t1 | D39: -1.2430646
A40: 24 | B40: 28 | C40: BVMT_t2 | D40: -1.4113293
A41: 24 | B41: 28 | C41: BVMT_t3 | D41: -2.8869871
A42: 24 | B42: 28 | C42: BVMT_total_recall | D42: -1.8980853
A43: 24 | B43: 28 | C43: BVMT_learning | D43: 0.3159416
A44: 24 | B44: 28 | C44: BVMT_delayed_recall | D44: -3.709807
A45: 24 | B45: 28 | C45: BVMT_percent_retained | D45: -1.1576827
A46: 24 | B46: 28 | C46: BVMT_hits | D46: -0.62850083
A47: 24 | B47: 28 | C47: BVMT_false_alarms
A48: 24 | B48: 28 | C48: BVMT_discrimination_index | D48: -0.62850083
A49: 24 | B49: 28 | C49: BVMT_response_bias | D49: -0.9250042
A50: 26 | B50: 30 | C50: age | D50: 0.46091256
A51: 26 | B51: 30 | C51: BVMT_t1 | D51: -0.58351266
A52: 26 | B52: 30 | C52: BVMT_t2 | D52: -0.48094336
A53: 26 | B53: 30 | C53: BVMT_t3 | D53: -4.0249689
A54: 26 | B54: 30 | C54: BVMT_total_recall | D54: -1.3087613
A55: 26 | B55: 30 | C55: BVMT_learning | D55: 0.013459075
A56: 26 | B56: 30 | C56: BVMT_delayed_recall | D56: -4.6508519
A57: 26 | B57: 30 | C57: BVMT_percent_retained | D57: -0.3941315
A58: 26 | B58: 30 | C58: BVMT_hits | D58: 0.10697926
A59: 26 | B59: 30 | C59: BVMT_false_alarms
A60: 26 | B60: 30 | C60: BVMT_discrimination_index | D60: 0.10697926
...

Sheet Sheet2
B2: group | C2: age | D2: BVMT_t1 | E2: BVMT_t2 | F2: BVMT_t3 | G2: BVMT_total_recall | H2: BVMT_learning | I2: BVMT_delayed_recall | J2: BVMT_percent_retained | K2: BVMT_hits | L2: BVMT_false_alarms | M2: BVMT_discrimination_index | N2: BVMT_response_bias
A3: 2 | B3: {=INDIRECT("Sheet1!A"&$A3) & "-" & INDIRECT("Sheet1!B"&$A3)} -> 18-22 | C3: {=ROUND(TRANSPOSE(INDIRECT("Sheet1!D"&$A3&":D"&A3+11))*-1,2)} -> 6.78 | D3: 2.07 | E3: 1.61 | F3: 3.44 | G3: 2.41 | H3: -1.21 | I3: 6.14 | J3: 11.92 | K3: -0.4 | L3: -0.18 | M3: -0.3 | N3: -0.54
A4: =A3+12 -> 14 | B4: {=INDIRECT("Sheet1!A"&$A4) & "-" & INDIRECT("Sheet1!B"&$A4)} -> 20-24 | C4: {=ROUND(TRANSPOSE(INDIRECT("Sheet1!D"&$A4&":D"&A4+11))*-1,2)} -> 0.5 | D4: 2.6 | E4: 3.78 | F4: 5.08 | G4: 4.59 | H4: -0.94 | I4: 0.65 | J4: 0.05 | K4: -0.32 | L4: -0.15 | M4: -0.17 | N4: -0.34
A5: =A4+12 -> 26 | B5: {=INDIRECT("Sheet1!A"&$A5) & "-" & INDIRECT("Sheet1!B"&$A5)} -> 22-26 | C5: {=ROUND(TRANSPOSE(INDIRECT("Sheet1!D"&$A5&":D"&A5+11))*-1,2)} -> -0.02 | D5: 1.61 | E5: 2.27 | F5: 2.86 | G5: 2.55 | H5: -0.51 | I5: 0.71 | J5: 0.01 | K5: 0 | L5: 0 | M5: 0 | N5: 0.01
A6: =A5+12 -> 38 | B6: {=INDIRECT("Sheet1!A"&$A6) & "-" & INDIRECT("Sheet1!B"&$A6)} -> 24-28 | C6: {=ROUND(TRANSPOSE(INDIRECT("Sheet1!D"&$A6&":D"&A6+11))*-1,2)} -> 0.68 | D6: 1.24 | E6: 1.41 | F6: 2.89 | G6: 1.9 | H6: -0.32 | I6: 3.71 | J6: 1.16 | K6: 0.63 | L6: 0 | M6: 0.63 | N6: 0.93
A7: =A6+12 -> 50 | B7: {=INDIRECT("Sheet1!A"&$A7) & "-" & INDIRECT("Sheet1!B"&$A7)} -> 26-30 | C7: {=ROUND(TRANSPOSE(INDIRECT("Sheet1!D"&$A7&":D"&A7+11))*-1,2)} -> -0.46 | D7: 0.58 | E7: 0.48 | F7: 4.02 | G7: 1.31 | H7: -0.01 | I7: 4.65 | J7: 0.39 | K7: -0.11 | L7: 0 | M7: -0.11 | N7: -0.09
A8: =A7+12 -> 62 | B8: {=INDIRECT("Sheet1!A"&$A8) & "-" & INDIRECT("Sheet1!B"&$A8)} -> 28-32 | C8: {=ROUND(TRANSPOSE(INDIRECT("Sheet1!D"&$A8&":D"&A8+11))*-1,2)} -> 0 | D8: 0.55 | E8: 0.82 | F8: 6.58 | G8: 1.87 | H8: 0 | I8: 5.55 | J8: 0.52 | K8: -0.07 | L8: 0 | M8: -0.07 | N8: -0.04
A9: =A8+12 -> 74 | B9: {=INDIRECT("Sheet1!A"&$A9) & "-" & INDIRECT("Sheet1!B"&$A9)} -> 30-34 | C9: {=ROUND(TRANSPOSE(INDIRECT("Sheet1!D"&$A9&":D"&A9+11))*-1,2)} -> 0.03 | D9: 0.85 | E9: 1.46 | F9: 6.99 | G9: 2.57 | H9: 0 | I9: 5.92 | J9: 1.08 | K9: 0.15 | L9: 0 | M9: 0.15 | N9: 0.53
A10: =A9+12 -> 86 | B10: {=INDIRECT("Sheet1!A"&$A10) & "-" & INDIRECT("Sheet1!B"&$A10)} -> 32-36 | C10: {=ROUND(TRANSPOSE(INDIRECT("Sheet1!D"&$A10&":D"&A10+11))*-1,2)} -> -0.24 | D10: 0.1 | E10: 1.58 | F10: 0.51 | G10: 0.83 | H10: 0.08 | I10: 0.79 | J10: 0.17 | K10: 0.27 | L10: 0 | M10: 0.27 | N10: 0.64
A11: =A10+12 -> 98 | B11: {=INDIRECT("Sheet1!A"&$A11) & "-" & INDIRECT("Sheet1!B"&$A11)} -> 34-38 | C11: {=ROUND(TRANSPOSE(INDIRECT("Sheet1!D"&$A11&":D"&A11+11))*-1,2)} -> 0.34 | D11: 0.6 | E11: 2.06 | F11: 0.28 | G11: 1.26 | H11: -0.01 | I11: 1.09 | J11: 0.82 | K11: 0.06 | L11: -0.08 | M11: 0.09 | N11: 0.06
A12: =A11+12 -> 110 | B12: {=INDIRECT("Sheet1!A"&$A12) & "-" & INDIRECT("Sheet1!B"&$A12)} -> 36-40 | C12: {=ROUND(TRANSPOSE(INDIRECT("Sheet1!D"&$A12&":D"&A12+11))*-1,2)} -> -0.01 | D12: 0.74 | E12: 1.35 | F12: 0.14 | G12: 0.93 | H12: -0.05 | I12: 0.73 | J12: 0.68 | K12: 0.03 | L12: -0.12 | M12: 0.08 | N12: 0
A13: =A12+12 -> 122 | B13: {=INDIRECT("Sheet1!A"&$A13) & "-" & INDIRECT("Sheet1!B"&$A13)} -> 38-42 | C13: {=ROUND(TRANSPOSE(INDIRECT("Sheet1!D"&$A13&":D"&A13+11))*-1,2)} -> -0.13 | D13: 0.47 | E13: 1.38 | F13: 2.36 | G13: 1.71 | H13: 0.07 | I13: 6.11 | J13: 6.37 | K13: 0 | L13: -0.14 | M13: 0.03 | N13: 0
A14: =A13+12 -> 134 | B14: {=INDIRECT("Sheet1!A"&$A14) & "-" & INDIRECT("Sheet1!B"&$A14)} -> 40-44 | C14: {=ROUND(TRANSPOSE(INDIRECT("Sheet1!D"&$A14&":D"&A14+11))*-1,2)} -> 0.05 | D14: 0.71 | E14: 1.23 | F14: 10.91 | G14: 2.18 | H14: 0.06 | I14: 14.58 | J14: 4.57 | K14: -0.39 | L14: -22.42 | M14: -0.25 | N14: -0.37
A15: =A14+12 -> 146 | B15: {=INDIRECT("Sheet1!A"&$A15) & "-" & INDIRECT("Sheet1!B"&$A15)} -> 42-46 | C15: {=ROUND(TRANSPOSE(INDIRECT("Sheet1!D"&$A15&":D"&A15+11))*-1,2)} -> -0.21 | D15: 0.55 | E15: 2.49 | F15: 11.18 | G15: 3.05 | H15: 0.13 | I15: 12.97 | J15: 4.05 | K15: -0.18 | L15: -0.17 | M15: -0.02 | N15: -0.19
... A28: =A27+12 -> 302 | B28: {=INDIRECT("Sheet1!A"&$A28) & "-" & INDIRECT("Sheet1!B"&$A28)} -> 68-72 | C28: {=ROUND(TRANSPOSE(INDIRECT("Sheet1!D"&$A28&":D"&A28+11))*-1,2)} -> -3.61 | D28: 0.04 | E28: 0 | F28: 1.01 | G28: 0.12 | H28: 0.26 | I28: 0.36 | J28: 0.01 | K28: 0.08 | L28: -0.96 | M28: 2.03 | N28: -0.06

Sheet master_raw
A1: A010-COG-X-BVM-Form | B1: 1 | C1: A011-COG-X-BVM-Form | D1: 1 | E1: A012-COG-X-BVM-Form | F1: 1 | G1: A013-COG-X-BVM-Form | H1: 1 | I1: A014-COG-X-BVM-Form | J1: 1 | K1: A015-COG-X-BVM-Form | L1: 1 | M1: A016-COG-X-BVM-Form | N1: 1 | O1: A017-COG-X-BVM-Form | P1: 1 | Q1: A018-COG-X-BVM-Form | R1: 1 | S1: A019-COG-X-BVM-Form | T1: 1 | U1: A020-COG-X-BVM-Form | V1: 1 | W1: A021-COG-X-BVM-Form | X1: 1 | Y1: A022-COG-X-BVM-Form | Z1: 1 | AA1: A023-COG-X-BVM-Form | AB1: 1 | AC1: A024-COG-X-BVM-Form | AD1: 1 | AE1: A025-COG-X-BVM-Form | AF1: 1 | AG1: A026-COG-X-BVM-Form | AH1: 1 | AI1: A027-COG-X-BVM-Form | AJ1: 1 | AK1: A028-COG-X-BVM-Form | AL1: 1 | AM1: A029-COG-X-BVM-Form | AN1: 1 | AO1: A030-COG-X-BVM-Form | AP1: 1 | AQ1: A031-COG-X-BVM-Form | AR1: 1 | AS1: A032-COG-X-BVM-Form | AT1: 1 | AU1: A033-COG-X-BVM-Form | AV1: 1 | AW1: A034-COG-X-BVM-Form | AX1: 1 | AY1: A035-COG-X-BVM-Form | AZ1: 1 | BA1: A036-COG-X-BVM-Form | BB1: 1 | BC1: A037-COG-X-BVM-Form | BD1: 1 | BE1: A038-COG-X-BVM-Form | BF1: 1 | BG1: A039-COG-X-BVM-Form | BH1: 1 | BI1: A040-COG-X-BVM-Form | BJ1: 1 | BK1: A041-COG-X-BVM-Form | BL1: 1 | BM1: A042-COG-X-BVM-Form | BN1: 1 | BO1: A043-COG-X-BVM-Form | BP1: 1 | BQ1: A044-COG-X-BVM-Form | BR1: 1 | BS1: A045-COG-X-BVM-Form | BT1: 1 | BU1: A046-COG-X-BVM-Form | BV1: 1 | BW1: A047-COG-X-BVM-Form | BX1: 1 | BY1: A048-COG-X-BVM-Form | BZ1: 1 | CA1: A049-COG-X-BVM-Form | CB1: 1 | CC1: A050-COG-X-BVM-Form | CD1: 1 | CE1: A051-COG-X-BVM-Form | CF1: 1 | CG1: A052-COG-X-BVM-Form | CH1: 1 | CI1: A053-COG-X-BVM-Form | CJ1: 1 | CK1: A054-COG-X-BVM-Form | CL1: 1 | CM1: A055-COG-X-BVM-Form | CN1: 1 | CO1: A056-COG-X-BVM-Form | CP1: 1 | CQ1: A057-COG-X-BVM-Form | CR1: 1 | CS1: A058-COG-X-BVM-Form | CT1: 1 | CU1: A059-COG-X-BVM-Form | CV1: 1 | CW1: A060-COG-X-BVM-Form | CX1: 1 | CY1: A061-COG-X-BVM-Form | CZ1: 1 | DA1: A062-COG-X-BVM-Form | DB1: 1 | DC1: A063-COG-X-BVM-Form | DD1: 1 | DE1: A064-COG-X-BVM-Form | DF1: 1 | DG1: A065-COG-X-BVM-Form | DH1: 1 | DI1: A066-COG-X-BVM-Form | DJ1: 1 | DK1: A067-COG-X-BVM-Form | DL1: 1 | DM1: A068-COG-X-BVM-Form | DN1: 1 | DO1: A069-COG-X-BVM-Form | DP1: 1 | DQ1: A070-COG-X-BVM-Form | DR1: 1 | DS1: A071-COG-X-BVM-Form | DT1: 1 | DU1: A072-COG-X-BVM-Form | DV1: 1 | DW1: A073-COG-X-BVM-Form | DX1: 1 | DY1: A074-COG-X-BVM-Form | DZ1: 1 | EA1: A075-COG-X-BVM-Form | EB1: 1 | EC1: A076-COG-X-BVM-Form | ED1: 1 | EE1: A077-COG-X-BVM-Form | EF1: 1 | EG1: A078-COG-X-BVM-Form | EH1: 1 | EI1: A079-COG-X-BVM-Form | EJ1: 1 | EK1: A080-COG-X-BVM-Form | EL1: 1 | EM1: A081-COG-X-BVM-Form | EN1: 1 | EO1: A082-COG-X-BVM-Form | EP1: 1 | EQ1: A083-COG-X-BVM-Form | ER1: 1 | ES1: A084-COG-X-BVM-Form | ET1: 1 | EU1: A085-COG-X-BVM-Form | EV1: 1 | EW1: A086-COG-X-BVM-Form | EX1: 1 | EY1: A087-COG-X-BVM-Form | EZ1: 1 | FA1: A088-COG-X-BVM-Form | FB1: 1 | FC1: A089-COG-X-BVM-Form | FD1: 1 | FE1: A090-COG-X-BVM-Form | FF1: 1 | FG1: A091-COG-X-BVM-Form | FH1: 1 | FI1: A092-COG-X-BVM-Form | FJ1: 1 | FK1: A093-COG-X-BVM-Form | FL1: 1 | FM1: A094-COG-X-BVM-Form | FN1: 1 | FO1: A095-COG-X-BVM-Form | FP1: 1 | FQ1: A096-COG-X-BVM-Form | FR1: 1 | FS1: A097-COG-X-BVM-Form | FT1: 1 | FU1: A098-COG-X-BVM-Form | FV1: 1 | FW1: A099-COG-X-BVM-Form | FX1: 1 | FY1: A100-COG-X-BVM-Form | FZ1: 1 | GA1: A101-COG-X-BVM-Form | GB1: 1 | GC1: A102-COG-X-BVM-Form | GD1: 1 | GE1: A103-COG-X-BVM-Form | GF1: 1 | GG1: A104-COG-X-BVM-Form | GH1: 1 | GI1: A105-COG-X-BVM-Form | GJ1: 1 | GK1: A106-COG-X-BVM-Form | GL1: 1 | GM1: A107-COG-X-BVM-Form | GN1: 1 | GO1: A108-COG-X-BVM-Form | GP1: 1 | GQ1: A109-COG-X-BVM-Form | GR1: 1
A2: A010-COG-X-BVM-T1Ti | B2: 76 | C2: A011-COG-X-BVM-T1Ti | E2: A012-COG-X-BVM-T1Ti | G2: A013-COG-X-BVM-T1Ti | H2: 41 | I2: A014-COG-X-BVM-T1Ti | J2: 26 | K2: A015-COG-X-BVM-T1Ti | L2: 28 | M2: A016-COG-X-BVM-T1Ti | N2: 24 | O2: A017-COG-X-BVM-T1Ti | P2: 20 | Q2: A018-COG-X-BVM-T1Ti | R2: 47 | S2: A019-COG-X-BVM-T1Ti | T2: 36 | U2: A020-COG-X-BVM-T1Ti | V2: 45 | W2: A021-COG-X-BVM-T1Ti | X2: 23 | Y2: A022-COG-X-BVM-T1Ti | Z2: 36 | AA2: A023-COG-X-BVM-T1Ti | AB2: 45 | AC2: A024-COG-X-BVM-T1Ti | AD2: 139 | AE2: A025-COG-X-BVM-T1Ti | AF2: 35 | AG2: A026-COG-X-BVM-T1Ti | AH2: 47 | AI2: A027-COG-X-BVM-T1Ti | AJ2: 34 | AK2: A028-COG-X-BVM-T1Ti | AL2: 16 | AM2: A029-COG-X-BVM-T1Ti | AN2: 22 | AO2: A030-COG-X-BVM-T1Ti | AP2: 31 | AQ2: A031-COG-X-BVM-T1Ti | AR2: 50 | AS2: A032-COG-X-BVM-T1Ti | AT2: 61 | AU2: A033-COG-X-BVM-T1Ti | AV2: 47 | AW2: A034-COG-X-BVM-T1Ti | AX2: 39 | AY2: A035-COG-X-BVM-T1Ti | AZ2: 45 | BA2: A036-COG-X-BVM-T1Ti | BB2: 44 | BC2: A037-COG-X-BVM-T1Ti | BD2: 25 | BE2: A038-COG-X-BVM-T1Ti | BF2: 16 | BG2: A039-COG-X-BVM-T1Ti | BH2: 62 | BI2: A040-COG-X-BVM-T1Ti | BJ2: 24 | BK2: A041-COG-X-BVM-T1Ti | BL2: 33 | BM2: A042-COG-X-BVM-T1Ti | BN2: 19 | BO2: A043-COG-X-BVM-T1Ti | BP2: 60 | BQ2: A044-COG-X-BVM-T1Ti | BR2: 40 | BS2: A045-COG-X-BVM-T1Ti | BT2: 58 | BU2: A046-COG-X-BVM-T1Ti | BV2: 40 | BW2: A047-COG-X-BVM-T1Ti | BX2: 33 | BY2: A048-COG-X-BVM-T1Ti | BZ2: 32 | CA2: A049-COG-X-BVM-T1Ti | CB2: 32 | CC2: A050-COG-X-BVM-T1Ti | CD2: 48 | CE2: A051-COG-X-BVM-T1Ti | CF2: 27 | CG2: A052-COG-X-BVM-T1Ti | CH2: 47 | CI2: A053-COG-X-BVM-T1Ti | CJ2: 45 | CK2: A054-COG-X-BVM-T1Ti | CL2: 48 | CM2: A055-COG-X-BVM-T1Ti | CN2: 34 | CO2: A056-COG-X-BVM-T1Ti | CP2: 23 | CQ2: A057-COG-X-BVM-T1Ti | CR2: 43 | CS2: A058-COG-X-BVM-T1Ti | CT2: 35 | CU2: A059-COG-X-BVM-T1Ti | CV2: 61 | CW2: A060-COG-X-BVM-T1Ti | CX2: 65 | CY2: A061-COG-X-BVM-T1Ti | CZ2: 54 | DA2: A062-COG-X-BVM-T1Ti | DB2: 52 | DC2: A063-COG-X-BVM-T1Ti | DD2: 50 | DE2: A064-COG-X-BVM-T1Ti | DF2: 34 | DG2: A065-COG-X-BVM-T1Ti | DH2: 42 | DI2: A066-COG-X-BVM-T1Ti | DJ2: 34 | DK2: A067-COG-X-BVM-T1Ti | DL2: 39 | DM2: A068-COG-X-BVM-T1Ti | DN2: 22 | DO2: A069-COG-X-BVM-T1Ti | DP2: 32 | DQ2: A070-COG-X-BVM-T1Ti | DR2: 37 | DS2: A071-COG-X-BVM-T1Ti | DU2: A072-COG-X-BVM-T1Ti | DV2: 32 | DW2: A073-COG-X-BVM-T1Ti | DX2: 25 | DY2: A074-COG-X-BVM-T1Ti | DZ2: 36 | EA2: A075-COG-X-BVM-T1Ti | EB2: 32 | EC2: A076-COG-X-BVM-T1Ti | ED2: 40 | EE2: A077-COG-X-BVM-T1Ti | EF2: 46 | EG2: A078-COG-X-BVM-T1Ti | EH2: 40 | EI2: A079-COG-X-BVM-T1Ti | EJ2: 71 | EK2: A080-COG-X-BVM-T1Ti | EL2: 41 | EM2: A081-COG-X-BVM-T1Ti | EN2: 46 | EO2: A082-COG-X-BVM-T1Ti | EP2: 50 | EQ2: A083-COG-X-BVM-T1Ti | ER2: 33 | ES2: A084-COG-X-BVM-T1Ti | ET2: 17 | EU2: A085-COG-X-BVM-T1Ti | EV2: 40 | EW2: A086-COG-X-BVM-T1Ti | EX2: 16 | EY2: A087-COG-X-BVM-T1Ti | EZ2: 35 | FA2: A088-COG-X-BVM-T1Ti | FB2: 30 | FC2: A089-COG-X-BVM-T1Ti | FD2: 34 | FE2: A090-COG-X-BVM-T1Ti | FF2: 36 | FG2: A091-COG-X-BVM-T1Ti | FH2: 23 | FI2: A092-COG-X-BVM-T1Ti | FJ2: 25 | FK2: A093-COG-X-BVM-T1Ti | FL2: 52 | FM2: A094-COG-X-BVM-T1Ti | FN2: 60 | FO2: A095-COG-X-BVM-T1Ti | FP2: 39 | FQ2: A096-COG-X-BVM-T1Ti | FR2: 57 | FS2: A097-COG-X-BVM-T1Ti | FT2: 16 | FU2: A098-COG-X-BVM-T1Ti | FV2: 40 | FW2: A099-COG-X-BVM-T1Ti | FX2: 41 | FY2: A100-COG-X-BVM-T1Ti | FZ2: 27 | GA2: A101-COG-X-BVM-T1Ti | GB2: 58 | GC2: A102-COG-X-BVM-T1Ti | GD2: 42 | GE2: A103-COG-X-BVM-T1Ti | GF2: 73 | GG2: A104-COG-X-BVM-T1Ti | GH2: 53 | GI2: A105-COG-X-BVM-T1Ti | GJ2: 23 | GK2: A106-COG-X-BVM-T1Ti | GL2: 70 | GM2: A107-COG-X-BVM-T1Ti | GN2: 34 | GO2: A108-COG-X-BVM-T1Ti | GP2: 47 | GQ2: A109-COG-X-BVM-T1Ti | GR2: 34
A3: A010-COG-X-BVM-T1Sc | B3: 11 | C3: A011-COG-X-BVM-T1Sc | D3: 10 | E3: A012-COG-X-BVM-T1Sc | F3: 8 | G3: A013-COG-X-BVM-T1Sc | H3: 7.5 | I3: A014-COG-X-BVM-T1Sc | J3: 11.5 | K3: A015-COG-X-BVM-T1Sc | L3: 7.5 | M3: A016-COG-X-BVM-T1Sc | N3: 11.5 | O3: A017-COG-X-BVM-T1Sc | P3: 9 | Q3: A018-COG-X-BVM-T1Sc | R3: 9.5 | S3: A019-COG-X-BVM-T1Sc | T3: 8.5 | U3: A020-COG-X-BVM-T1Sc | V3: 8.5 | W3: A021-COG-X-BVM-T1Sc | X3: 10 | Y3: A022-COG-X-BVM-T1Sc | Z3: 6.5 | AA3: A023-COG-X-BVM-T1Sc | AB3: 5 | AC3: A024-COG-X-BVM-T1Sc | AD3: 5 | AE3: A025-COG-X-BVM-T1Sc | AF3: 9 | AG3: A026-COG-X-BVM-T1Sc | AH3: 9.5 | AI3: A027-COG-X-BVM-T1Sc | AJ3: 12 | AK3: A028-COG-X-BVM-T1Sc | AL3: 10 | AM3: A029-COG-X-BVM-T1Sc | AN3: 11.5 | AO3: A030-COG-X-BVM-T1Sc | AP3: 9 | AQ3: A031-COG-X-BVM-T1Sc | AR3: 6 | AS3: A032-COG-X-BVM-T1Sc | AT3: 7.5 | AU3: A033-COG-X-BVM-T1Sc | AV3: 5 | AW3: A034-COG-X-BVM-T1Sc | AX3: 10 | AY3: A035-COG-X-BVM-T1Sc | AZ3: 10 | BA3: A036-COG-X-BVM-T1Sc | BB3: 8.5 | BC3: A037-COG-X-BVM-T1Sc | BD3: 12 | BE3: A038-COG-X-BVM-T1Sc | BF3: 7 | BG3: A039-COG-X-BVM-T1Sc | BH3: 8.5 | BI3: A040-COG-X-BVM-T1Sc | BJ3: 7.5 | BK3: A041-COG-X-BVM-T1Sc | BL3: 8 | BM3: A042-COG-X-BVM-T1Sc | BN3: 5 | BO3: A043-COG-X-BVM-T1Sc | BP3: 7 | BQ3: A044-COG-X-BVM-T1Sc | BR3: 9.5 | BS3: A045-COG-X-BVM-T1Sc | BT3: 7 | BU3: A046-COG-X-BVM-T1Sc | BV3: 9.5 | BW3: A047-COG-X-BVM-T1Sc | BX3: 7 | BY3: A048-COG-X-BVM-T1Sc | BZ3: 9.5 | CA3: A049-COG-X-BVM-T1Sc | CB3: 5.5 | CC3: A050-COG-X-BVM-T1Sc | CD3: 8.5 | CE3: A051-COG-X-BVM-T1Sc | CF3: 4.5 | CG3: A052-COG-X-BVM-T1Sc | CH3: 8 | CI3: A053-COG-X-BVM-T1Sc | CJ3: 8.5 | CK3: A054-COG-X-BVM-T1Sc | CL3: 11.5 | CM3: A055-COG-X-BVM-T1Sc | CN3: 5.5 | CO3: A056-COG-X-BVM-T1Sc | CP3: 7.5 | CQ3: A057-COG-X-BVM-T1Sc | CR3: 8 | CS3: A058-COG-X-BVM-T1Sc | CT3: 6 | CU3: A059-COG-X-BVM-T1Sc | CV3: 9 | CW3: A060-COG-X-BVM-T1Sc | CX3: 9 | CY3: A061-COG-X-BVM-T1Sc | CZ3: 4 | DA3: A062-COG-X-BVM-T1Sc | DB3: 7 | DC3: A063-COG-X-BVM-T1Sc | DD3: 6 | DE3: A064-COG-X-BVM-T1Sc | DF3: 8 | DG3: A065-COG-X-BVM-T1Sc | DH3: 5 | DI3: A066-COG-X-BVM-T1Sc | DJ3: 4 | DK3: A067-COG-X-BVM-T1Sc | DL3: 6 | DM3: A068-COG-X-BVM-T1Sc | DN3: 8 | DO3: A069-COG-X-BVM-T1Sc | DP3: 5.5 | DQ3: A070-COG-X-BVM-T1Sc | DR3: 9.5 | DS3: A071-COG-X-BVM-T1Sc | DT3: 7 | DU3: A072-COG-X-BVM-T1Sc | DV3: 9.5 | DW3: A073-COG-X-BVM-T1Sc | DX3: 5.5 | DY3: A074-COG-X-BVM-T1Sc | DZ3: 8 | EA3: A075-COG-X-BVM-T1Sc | EB3: 7.5 | EC3: A076-COG-X-BVM-T1Sc | ED3: 3.5 | EE3: A077-COG-X-BVM-T1Sc | EF3: 8 | EG3: A078-COG-X-BVM-T1Sc | EH3: 4 | EI3: A079-COG-X-BVM-T1Sc | EJ3: 11 | EK3: A080-COG-X-BVM-T1Sc | EL3: 5.5 | EM3: A081-COG-X-BVM-T1Sc | EN3: 8 | EO3: A082-COG-X-BVM-T1Sc | EP3: 9 | EQ3: A083-COG-X-BVM-T1Sc | ER3: 5.5 | ES3: A084-COG-X-BVM-T1Sc | ET3: 6 | EU3: A085-COG-X-BVM-T1Sc | EV3: 5.5 | EW3: A086-COG-X-BVM-T1Sc | EX3: 5.5 | EY3: A087-COG-X-BVM-T1Sc | EZ3: 9 | FA3: A088-COG-X-BVM-T1Sc | FB3: 2 | FC3: A089-COG-X-BVM-T1Sc | FD3: 6 | FE3: A090-COG-X-BVM-T1Sc | FF3: 2.5 | FG3: A091-COG-X-BVM-T1Sc | FH3: 5 | FI3: A092-COG-X-BVM-T1Sc | FJ3: 5 | FK3: A093-COG-X-BVM-T1Sc | FL3: 7 | FM3: A094-COG-X-BVM-T1Sc | FN3: 4.5 | FO3: A095-COG-X-BVM-T1Sc | FP3: 6.5 | FQ3: A096-COG-X-BVM-T1Sc | FR3: 5 | FS3: A097-COG-X-BVM-T1Sc | FT3: 5.5 | FU3: A098-COG-X-BVM-T1Sc | FV3: 5.5 | FW3: A099-COG-X-BVM-T1Sc | FX3: 5.5 | FY3: A100-COG-X-BVM-T1Sc | FZ3: 2 | GA3: A101-COG-X-BVM-T1Sc | GB3: 5 | GC3: A102-COG-X-BVM-T1Sc | GD3: 10.5 | GE3: A103-COG-X-BVM-T1Sc | GF3: 8 | GG3: A104-COG-X-BVM-T1Sc | GH3: 4.5 | GI3: A105-COG-X-BVM-T1Sc | GJ3: 3 | GK3: A106-COG-X-BVM-T1Sc | GL3: 8 | GM3: A107-COG-X-BVM-T1Sc | GN3: 3.5 | GO3: A108-COG-X-BVM-T1Sc | GP3: 6.5 | GQ3: A109-COG-X-BVM-T1Sc | GR3: 2
A4: A010-COG-X-BVM-T2Ti | B4: 70 | C4: A011-COG-X-BVM-T2Ti | E4: A012-COG-X-BVM-T2Ti | G4: A013-COG-X-BVM-T2Ti | H4: 31 | I4: A014-COG-X-BVM-T2Ti | J4: 38 | K4: A015-COG-X-BVM-T2Ti | L4: 25 | M4: A016-COG-X-BVM-T2Ti | N4: 22 | O4: A017-COG-X-BVM-T2Ti | P4: 26 | Q4: A018-COG-X-BVM-T2Ti | R4: 31 | S4: A019-COG-X-BVM-T2Ti | T4: 31 | U4: A020-COG-X-BVM-T2Ti | V4: 36 | W4: A021-COG-X-BVM-T2Ti | X4: 21 | Y4: A022-COG-X-BVM-T2Ti | Z4: 41 | AA4: A023-COG-X-BVM-T2Ti | AB4: 78 | AC4: A024-COG-X-BVM-T2Ti | AD4: 49 | AE4: A025-COG-X-BVM-T2Ti | AF4: 39 | AG4: A026-COG-X-BVM-T2Ti | AH4: 42 | AI4: A027-COG-X-BVM-T2Ti | AJ4: 28 | AK4: A028-COG-X-BVM-T2Ti | AL4: 17 | AM4: A029-COG-X-BVM-T2Ti | AN4: 26 | AO4: A030-COG-X-BVM-T2Ti | AP4: 24 | AQ4: A031-COG-X-BVM-T2Ti | AR4: 37 | AS4: A032-COG-X-BVM-T2Ti | AT4: 34 | AU4: A033-COG-X-BVM-T2Ti | AV4: 56 | AW4: A034-COG-X-BVM-T2Ti | AX4: 32 | AY4: A035-COG-X-BVM-T2Ti | AZ4: 48 | BA4: A036-COG-X-BVM-T2Ti | BB4: 57 | BC4: A037-COG-X-BVM-T2Ti | BD4: 24 | BE4: A038-COG-X-BVM-T2Ti | BF4: 31 | BG4: A039-COG-X-BVM-T2Ti | BH4: 33 | BI4: A040-COG-X-BVM-T2Ti | BJ4: 26 | BK4: A041-COG-X-BVM-T2Ti | BL4: 19 | BM4: A042-COG-X-BVM-T2Ti | BN4: 36 | BO4: A043-COG-X-BVM-T2Ti | BP4: 54 | BQ4: A044-COG-X-BVM-T2Ti | BR4: 37 | BS4: A045-COG-X-BVM-T2Ti | BT4: 43 | BU4: A046-COG-X-BVM-T2Ti | BV4: 34 | BW4: A047-COG-X-BVM-T2Ti | BX4: 32 | BY4: A048-COG-X-BVM-T2Ti | BZ4: 16 | CA4: A049-COG-X-BVM-T2Ti | CB4: 48 | CC4: A050-COG-X-BVM-T2Ti | CD4: 43 | CE4: A051-COG-X-BVM-T2Ti | CF4: 29 | CG4: A052-COG-X-BVM-T2Ti | CH4: 52 | CI4: A053-COG-X-BVM-T2Ti | CJ4: 55 | CK4: A054-COG-X-BVM-T2Ti | CL4: 34 | CM4: A055-COG-X-BVM-T2Ti | CN4: 40 | CO4: A056-COG-X-BVM-T2Ti | CP4: 25 | CQ4: A057-COG-X-BVM-T2Ti | CR4: 35 | CS4: A058-COG-X-BVM-T2Ti | CT4: 33 | CU4: A059-COG-X-BVM-T2Ti | CV4: 53 | CW4: A060-COG-X-BVM-T2Ti | CX4: 47 | CY4: A061-COG-X-BVM-T2Ti | CZ4: 42 | DA4: A062-COG-X-BVM-T2Ti | DB4: 43 | DC4: A063-COG-X-BVM-T2Ti | DD4: 65 | DE4: A064-COG-X-BVM-T2Ti | DF4: 27 | DG4: A065-COG-X-BVM-T2Ti | DH4: 56 | DI4: A066-COG-X-BVM-T2Ti | DJ4: 20 | DK4: A067-COG-X-BVM-T2Ti | DL4: 34 | DM4: A068-COG-X-BVM-T2Ti | DN4: 25 | DO4: A069-COG-X-BVM-T2Ti | DP4: 36 | DQ4: A070-COG-X-BVM-T2Ti | DR4: 30 | DS4: A071-COG-X-BVM-T2Ti | DU4: A072-COG-X-BVM-T2Ti | DV4: 20 | DW4: A073-COG-X-BVM-T2Ti | DX4: 27 | DY4: A074-COG-X-BVM-T2Ti | DZ4: 32 | EA4: A075-COG-X-BVM-T2Ti | EB4: 50 | EC4: A076-COG-X-BVM-T2Ti | ED4: 36 | EE4: A077-COG-X-BVM-T2Ti | EF4: 32 | EG4: A078-COG-X-BVM-T2Ti | EH4: 45 | EI4: A079-COG-X-BVM-T2Ti | EJ4: 32 | EK4: A080-COG-X-BVM-T2Ti | EL4: 34 | EM4: A081-COG-X-BVM-T2Ti | EN4: 57 | EO4: A082-COG-X-BVM-T2Ti | EP4: 47 | EQ4: A083-COG-X-BVM-T2Ti | ER4: 41 | ES4: A084-COG-X-BVM-T2Ti | ET4: 30 | EU4: A085-COG-X-BVM-T2Ti | EV4: 45 | EW4: A086-COG-X-BVM-T2Ti | EX4: 26 | EY4: A087-COG-X-BVM-T2Ti | EZ4: 38 | FA4: A088-COG-X-BVM-T2Ti | FB4: 37 | FC4: A089-COG-X-BVM-T2Ti | FD4: 30 | FE4: A090-COG-X-BVM-T2Ti | FF4: 31 | FG4: A091-COG-X-BVM-T2Ti | FH4: 41 | FI4: A092-COG-X-BVM-T2Ti | FJ4: 48 | FK4: A093-COG-X-BVM-T2Ti | FL4: 49 | FM4: A094-COG-X-BVM-T2Ti | FN4: 50 | FO4: A095-COG-X-BVM-T2Ti | FP4: 52 | FQ4: A096-COG-X-BVM-T2Ti | FR4: 84 | FS4: A097-COG-X-BVM-T2Ti | FT4: 21 | FU4: A098-COG-X-BVM-T2Ti | FV4: 39 | FW4: A099-COG-X-BVM-T2Ti | FX4: 55 | FY4: A100-COG-X-BVM-T2Ti | FZ4: 25 | GA4: A101-COG-X-BVM-T2Ti | GB4: 82 | GC4: A102-COG-X-BVM-T2Ti | GD4: 41 | GE4: A103-COG-X-BVM-T2Ti | GF4: 72 | GG4: A104-COG-X-BVM-T2Ti | GH4: 65 | GI4: A105-COG-X-BVM-T2Ti | GJ4: 36 | GK4: A106-COG-X-BVM-T2Ti | GL4: 70 | GM4: A107-COG-X-BVM-T2Ti | GN4: 43 | GO4: A108-COG-X-BVM-T2Ti | GP4: 31 | GQ4: A109-COG-X-BVM-T2Ti | GR4: 36
A5: A010-COG-X-BVM-T2Sc | B5: 12 | C5: A011-COG-X-BVM-T2Sc | D5: 12 | E5: A012-COG-X-BVM-T2Sc | F5: 11.5 | G5: A013-COG-X-BVM-T2Sc | H5: 9.5 | I5: A014-COG-X-BVM-T2Sc | J5: 12 | K5: A015-COG-X-BVM-T2Sc | L5: 12 | M5: A016-COG-X-BVM-T2Sc | N5: 11.5 | O5: A017-COG-X-BVM-T2Sc | P5: 11.5 | Q5: A018-COG-X-BVM-T2Sc | R5: 12 | S5: A019-COG-X-BVM-T2Sc | T5: 11.5 | U5: A020-COG-X-BVM-T2Sc | V5: 11 | W5: A021-COG-X-BVM-T2Sc | X5: 11 | Y5: A022-COG-X-BVM-T2Sc | Z5: 9.5 | AA5: A023-COG-X-BVM-T2Sc | AB5: 9 | AC5: A024-COG-X-BVM-T2Sc | AD5: 11.5 | AE5: A025-COG-X-BVM-T2Sc | AF5: 12 | AG5: A026-COG-X-BVM-T2Sc | AH5: 10 | AI5: A027-COG-X-BVM-T2Sc | AJ5: 12 | AK5: A028-COG-X-BVM-T2Sc | AL5: 12 | AM5: A029-COG-X-BVM-T2Sc | AN5: 12 | AO5: A030-COG-X-BVM-T2Sc | AP5: 12 | AQ5: A031-COG-X-BVM-T2Sc | AR5: 12 | AS5: A032-COG-X-BVM-T2Sc | AT5: 12 | AU5: A033-COG-X-BVM-T2Sc | AV5: 9 | AW5: A034-COG-X-BVM-T2Sc | AX5: 12 | AY5: A035-COG-X-BVM-T2Sc | AZ5: 12 | BA5: A036-COG-X-BVM-T2Sc | BB5: 8 | BC5: A037-COG-X-BVM-T2Sc | BD5: 12 | BE5: A038-COG-X-BVM-T2Sc | BF5: 9.5 | BG5: A039-COG-X-BVM-T2Sc | BH5: 11.5 | BI5: A040-COG-X-BVM-T2Sc | BJ5: 8 | BK5: A041-COG-X-BVM-T2Sc | BL5: 12 | BM5: A042-COG-X-BVM-T2Sc | BN5: 11.5 | BO5: A043-COG-X-BVM-T2Sc | BP5: 12 | BQ5: A044-COG-X-BVM-T2Sc | BR5: 10 | BS5: A045-COG-X-BVM-T2Sc | BT5: 11 | BU5: A046-COG-X-BVM-T2Sc | BV5: 11.5 | BW5: A047-COG-X-BVM-T2Sc | BX5: 8.5 | BY5: A048-COG-X-BVM-T2Sc | BZ5: 11.5 | CA5: A049-COG-X-BVM-T2Sc | CB5: 12 | CC5: A050-COG-X-BVM-T2Sc | CD5: 12 | CE5: A051-COG-X-BVM-T2Sc | CF5: 7 | CG5: A052-COG-X-BVM-T2Sc | CH5: 11.5 | CI5: A053-COG-X-BVM-T2Sc | CJ5: 11.5 | CK5: A054-COG-X-BVM-T2Sc | CL5: 12 | CM5: A055-COG-X-BVM-T2Sc | CN5: 7 | CO5: A056-COG-X-BVM-T2Sc | CP5: 11 | CQ5: A057-COG-X-BVM-T2Sc | CR5: 12 | CS5: A058-COG-X-BVM-T2Sc | CT5: 10 | CU5: A059-COG-X-BVM-T2Sc | CV5: 12 | CW5: A060-COG-X-BVM-T2Sc | CX5: 11 | CY5: A061-COG-X-BVM-T2Sc | CZ5: 11.5 | DA5: A062-COG-X-BVM-T2Sc | DB5: 11 | DC5: A063-COG-X-BVM-T2Sc | DD5: 11.5 | DE5: A064-COG-X-BVM-T2Sc | DF5: 12 | DG5: A065-COG-X-BVM-T2Sc | DH5: 7 | DI5: A066-COG-X-BVM-T2Sc | DJ5: 6 | DK5: A067-COG-X-BVM-T2Sc | DL5: 7.5 | DM5: A068-COG-X-BVM-T2Sc | DN5: 11 | DO5: A069-COG-X-BVM-T2Sc | DP5: 11.5 | DQ5: A070-COG-X-BVM-T2Sc | DR5: 11.5 | DS5: A071-COG-X-BVM-T2Sc | DT5: 11 | DU5: A072-COG-X-BVM-T2Sc | DV5: 12 | DW5: A073-COG-X-BVM-T2Sc | DX5: 9 | DY5: A074-COG-X-BVM-T2Sc | DZ5: 10 | EA5: A075-COG-X-BVM-T2Sc | EB5: 9.5 | EC5: A076-COG-X-BVM-T2Sc | ED5: 7.5 | EE5: A077-COG-X-BVM-T2Sc | EF5: 12 | EG5: A078-COG-X-BVM-T2Sc | EH5: 6 | EI5: A079-COG-X-BVM-T2Sc | EJ5: 12 | EK5: A080-COG-X-BVM-T2Sc | EL5: 11.5 | EM5: A081-COG-X-BVM-T2Sc | EN5: 10 | EO5: A082-COG-X-BVM-T2Sc | EP5: 11.5 | EQ5: A083-COG-X-BVM-T2Sc | ER5: 9 | ES5: A084-COG-X-BVM-T2Sc | ET5: 6.5 | EU5: A085-COG-X-BVM-T2Sc | EV5: 9 | EW5: A086-COG-X-BVM-T2Sc | EX5: 12 | EY5: A087-COG-X-BVM-T2Sc | EZ5: 11 | FA5: A088-COG-X-BVM-T2Sc | FB5: 10 | FC5: A089-COG-X-BVM-T2Sc | FD5: 10 | FE5: A090-COG-X-BVM-T2Sc | FF5: 10 | FG5: A091-COG-X-BVM-T2Sc | FH5: 8.5 | FI5: A092-COG-X-BVM-T2Sc | FJ5: 11 | FK5: A093-COG-X-BVM-T2Sc | FL5: 11 | FM5: A094-COG-X-BVM-T2Sc | FN5: 8 | FO5: A095-COG-X-BVM-T2Sc | FP5: 11.5 | FQ5: A096-COG-X-BVM-T2Sc | FR5: 9 | FS5: A097-COG-X-BVM-T2Sc | FT5: 5.5 | FU5: A098-COG-X-BVM-T2Sc | FV5: 9.5 | FW5: A099-COG-X-BVM-T2Sc | FX5: 9 | FY5: A100-COG-X-BVM-T2Sc | FZ5: 3.5 | GA5: A101-COG-X-BVM-T2Sc | GB5: 10.5 | GC5: A102-COG-X-BVM-T2Sc | GD5: 11.5 | GE5: A103-COG-X-BVM-T2Sc | GF5: 7.5 | GG5: A104-COG-X-BVM-T2Sc | GH5: 11.5 | GI5: A105-COG-X-BVM-T2Sc | GJ5: 4.5 | GK5: A106-COG-X-BVM-T2Sc | GL5: 11.5 | GM5: A107-COG-X-BVM-T2Sc | GN5: 6.5 | GO5: A108-COG-X-BVM-T2Sc | GP5: 9 | GQ5: A109-COG-X-BVM-T2Sc | GR5: 3.5
A6: A010-COG-X-BVM-T3Ti | B6: 66 | C6: A011-COG-X-BVM-T3Ti | E6: A012-COG-X-BVM-T3Ti | G6: A013-COG-X-BVM-T3Ti | H6: 35 | I6: A014-COG-X-BVM-T3Ti | J6: 47 | K6: A015-COG-X-BVM-T3Ti | L6: 30 | M6: A016-COG-X-BVM-T3Ti | N6: 21 | O6: A017-COG-X-BVM-T3Ti | P6: 25 | Q6: A018-COG-X-BVM-T3Ti | R6: 32 | S6: A019-COG-X-BVM-T3Ti | T6: 29 | U6: A020-COG-X-BVM-T3Ti | V6: 38 | W6: A021-COG-X-BVM-T3Ti | X6: 28 | Y6: A022-COG-X-BVM-T3Ti | Z6: 24 | AA6: A023-COG-X-BVM-T3Ti | AB6: 71 | AC6: A024-COG-X-BVM-T3Ti | AD6: 49 | AE6: A025-COG-X-BVM-T3Ti | AF6: 55 | AG6: A026-COG-X-BVM-T3Ti | AH6: 34 | AI6: A027-COG-X-BVM-T3Ti | AJ6: 32 | AK6: A028-COG-X-BVM-T3Ti | AL6: 21 | AM6: A029-COG-X-BVM-T3Ti | AN6: 20 | AO6: A030-COG-X-BVM-T3Ti | AP6: 18 | AQ6: A031-COG-X-BVM-T3Ti | AR6: 25 | AS6: A032-COG-X-BVM-T3Ti | AT6: 41 | AU6: A033-COG-X-BVM-T3Ti | AV6: 35 | AW6: A034-COG-X-BVM-T3Ti | AX6: 35 | AY6: A035-COG-X-BVM-T3Ti | AZ6: 36 | BA6: A036-COG-X-BVM-T3Ti | BB6: 61 | BC6: A037-COG-X-BVM-T3Ti | BD6: 25 | BE6: A038-COG-X-BVM-T3Ti | BF6: 33 | BG6: A039-COG-X-BVM-T3Ti | BH6: 31 | BI6: A040-COG-X-BVM-T3Ti | BJ6: 25 | BK6: A041-COG-X-BVM-T3Ti | BL6: 22 | BM6: A042-COG-X-BVM-T3Ti | BN6: 33 | BO6: A043-COG-X-BVM-T3Ti | BP6: 41 | BQ6: A044-COG-X-BVM-T3Ti | BR6: 38 | BS6: A045-COG-X-BVM-T3Ti | BT6: 36 | BU6: A046-COG-X-BVM-T3Ti | BV6: 28 | BW6: A047-COG-X-BVM-T3Ti | BX6: 30 | BY6: A048-COG-X-BVM-T3Ti | BZ6: 14 | CA6: A049-COG-X-BVM-T3Ti | CB6: 39 | CC6: A050-COG-X-BVM-T3Ti | CD6: 27 | CE6: A051-COG-X-BVM-T3Ti | CF6: 35 | CG6: A052-COG-X-BVM-T3Ti | CH6: 58 | CI6: A053-COG-X-BVM-T3Ti | CJ6: 42 | CK6: A054-COG-X-BVM-T3Ti | CL6: 34 | CM6: A055-COG-X-BVM-T3Ti | CN6: 36 | CO6: A056-COG-X-BVM-T3Ti | CP6: 32 | CQ6: A057-COG-X-BVM-T3Ti | CR6: 35 | CS6: A058-COG-X-BVM-T3Ti | CT6: 25 | CU6: A059-COG-X-BVM-T3Ti | CV6: 52 | CW6: A060-COG-X-BVM-T3Ti | CX6: 43 | CY6: A061-COG-X-BVM-T3Ti | CZ6: 37 | DA6: A062-COG-X-BVM-T3Ti | DB6: 23 | DC6: A063-COG-X-BVM-T3Ti | DD6: 35 | DE6: A064-COG-X-BVM-T3Ti | DF6: 28 | DG6: A065-COG-X-BVM-T3Ti | DH6: 44 | DI6: A066-COG-X-BVM-T3Ti | DJ6: 23 | DK6: A067-COG-X-BVM-T3Ti | DL6: 23 | DM6: A068-COG-X-BVM-T3Ti | DN6: 21 | DO6: A069-COG-X-BVM-T3Ti | DP6: 52 | DQ6: A070-COG-X-BVM-T3Ti | DR6: 32 | DS6: A071-COG-X-BVM-T3Ti | DU6: A072-COG-X-BVM-T3Ti | DV6: 17 | DW6: A073-COG-X-BVM-T3Ti | DX6: 30 | DY6: A074-COG-X-BVM-T3Ti | DZ6: 24 | EA6: A075-COG-X-BVM-T3Ti | EB6: 31 | EC6: A076-COG-X-BVM-T3Ti | ED6: 37 | EE6: A077-COG-X-BVM-T3Ti | EF6: 37 | EG6: A078-COG-X-BVM-T3Ti | EH6: 45 | EI6: A079-COG-X-BVM-T3Ti | EJ6: 36 | EK6: A080-COG-X-BVM-T3Ti | EL6: 40 | EM6: A081-COG-X-BVM-T3Ti | EN6: 46 | EO6: A082-COG-X-BVM-T3Ti | EP6: 43 | EQ6: A083-COG-X-BVM-T3Ti | ER6: 39 | ES6: A084-COG-X-BVM-T3Ti | ET6: 30 | EU6: A085-COG-X-BVM-T3Ti | EV6: 45 | EW6: A086-COG-X-BVM-T3Ti | EX6: 26 | EY6: A087-COG-X-BVM-T3Ti | EZ6: 32 | FA6: A088-COG-X-BVM-T3Ti | FB6: 37 | FC6: A089-COG-X-BVM-T3Ti | FD6: 31 | FE6: A090-COG-X-BVM-T3Ti | FF6: 33 | FG6: A091-COG-X-BVM-T3Ti | FH6: 37 | FI6: A092-COG-X-BVM-T3Ti | FJ6: 42 | FK6: A093-COG-X-BVM-T3Ti | FL6: 44 | FM6: A094-COG-X-BVM-T3Ti | FN6: 38 | FO6: A095-COG-X-BVM-T3Ti | FP6: 32 | FQ6: A096-COG-X-BVM-T3Ti | FR6: 73 | FS6: A097-COG-X-BVM-T3Ti | FT6: 30 | FU6: A098-COG-X-BVM-T3Ti | FV6: 38 | FW6: A099-COG-X-BVM-T3Ti | FX6: 45 | FY6: A100-COG-X-BVM-T3Ti | FZ6: 30 | GA6: A101-COG-X-BVM-T3Ti | GB6: 73 | GC6: A102-COG-X-BVM-T3Ti | GD6: 41 | GE6: A103-COG-X-BVM-T3Ti | GF6: 70 | GG6: A104-COG-X-BVM-T3Ti | GH6: 44 | GI6: A105-COG-X-BVM-T3Ti | GJ6: 62 | GK6: A106-COG-X-BVM-T3Ti | GL6: 50 | GM6: A107-COG-X-BVM-T3Ti | GN6: 33 | GO6: A108-COG-X-BVM-T3Ti | GP6: 46 | GQ6: A109-COG-X-BVM-T3Ti | GR6: 39
A7: A010-COG-X-BVM-T3Sc | B7: 12 | C7: A011-COG-X-BVM-T3Sc | D7: 12 | E7: A012-COG-X-BVM-T3Sc | F7: 12 | G7: A013-COG-X-BVM-T3Sc | H7: 11.5 | I7: A014-COG-X-BVM-T3Sc | J7: 12 | K7: A015-COG-X-BVM-T3Sc | L7: 12 | M7: A016-COG-X-BVM-T3Sc | N7: 12 | O7: A017-COG-X-BVM-T3Sc | P7: 12 | Q7: A018-COG-X-BVM-T3Sc | R7: 12 | S7: A019-COG-X-BVM-T3Sc | T7: 11.5 | U7: A020-COG-X-BVM-T3Sc | V7: 12 | W7: A021-COG-X-BVM-T3Sc | X7: 12 | Y7: A022-COG-X-BVM-T3Sc | Z7: 12 | AA7: A023-COG-X-BVM-T3Sc | AB7: 10.5 | AC7: A024-COG-X-BVM-T3Sc | AD7: 12 | AE7: A025-COG-X-BVM-T3Sc | AF7: 12 | AG7: A026-COG-X-BVM-T3Sc | AH7: 12 | AI7: A027-COG-X-BVM-T3Sc | AJ7: 12 | AK7: A028-COG-X-BVM-T3Sc | AL7: 12 | AM7: A029-COG-X-BVM-T3Sc | AN7: 12 | AO7: A030-COG-X-BVM-T3Sc | AP7: 12 | AQ7: A031-COG-X-BVM-T3Sc | AR7: 12 | AS7: A032-COG-X-BVM-T3Sc | AT7: 12 | AU7: A033-COG-X-BVM-T3Sc | AV7: 12 | AW7: A034-COG-X-BVM-T3Sc | AX7: 12 | AY7: A035-COG-X-BVM-T3Sc | AZ7: 12 | BA7: A036-COG-X-BVM-T3Sc | BB7: 12 | BC7: A037-COG-X-BVM-T3Sc | BD7: 12 | BE7: A038-COG-X-BVM-T3Sc | BF7: 11 | BG7: A039-COG-X-BVM-T3Sc | BH7: 12 | BI7: A040-COG-X-BVM-T3Sc | BJ7: 9 | BK7: A041-COG-X-BVM-T3Sc | BL7: 12 | BM7: A042-COG-X-BVM-T3Sc | BN7: 10 | BO7: A043-COG-X-BVM-T3Sc | BP7: 12 | BQ7: A044-COG-X-BVM-T3Sc | BR7: 12 | BS7: A045-COG-X-BVM-T3Sc | BT7: 11 | BU7: A046-COG-X-BVM-T3Sc | BV7: 12 | BW7: A047-COG-X-BVM-T3Sc | BX7: 7 | BY7: A048-COG-X-BVM-T3Sc | BZ7: 12 | CA7: A049-COG-X-BVM-T3Sc | CB7: 12 | CC7: A050-COG-X-BVM-T3Sc | CD7: 12 | CE7: A051-COG-X-BVM-T3Sc | CF7: 11 | CG7: A052-COG-X-BVM-T3Sc | CH7: 12 | CI7: A053-COG-X-BVM-T3Sc | CJ7: 11.5 | CK7: A054-COG-X-BVM-T3Sc | CL7: 12 | CM7: A055-COG-X-BVM-T3Sc | CN7: 11.5 | CO7: A056-COG-X-BVM-T3Sc | CP7: 12 | CQ7: A057-COG-X-BVM-T3Sc | CR7: 12 | CS7: A058-COG-X-BVM-T3Sc | CT7: 12 | CU7: A059-COG-X-BVM-T3Sc | CV7: 12 | CW7: A060-COG-X-BVM-T3Sc | CX7: 11.5 | CY7: A061-COG-X-BVM-T3Sc | CZ7: 11.5 | DA7: A062-COG-X-BVM-T3Sc | DB7: 12 | DC7: A063-COG-X-BVM-T3Sc | DD7: 11.5 | DE7: A064-COG-X-BVM-T3Sc | DF7: 12 | DG7: A065-COG-X-BVM-T3Sc | DH7: 8.5 | DI7: A066-COG-X-BVM-T3Sc | DJ7: 10.5 | DK7: A067-COG-X-BVM-T3Sc | DL7: 11 | DM7: A068-COG-X-BVM-T3Sc | DN7: 12 | DO7: A069-COG-X-BVM-T3Sc | DP7: 11.5 | DQ7: A070-COG-X-BVM-T3Sc | DR7: 11.5 | DS7: A071-COG-X-BVM-T3Sc | DT7: 12 | DU7: A072-COG-X-BVM-T3Sc | DV7: 12 | DW7: A073-COG-X-BVM-T3Sc | DX7: 11 | DY7: A074-COG-X-BVM-T3Sc | DZ7: 12 | EA7: A075-COG-X-BVM-T3Sc | EB7: 11.5 | EC7: A076-COG-X-BVM-T3Sc | ED7: 9.5 | EE7: A077-COG-X-BVM-T3Sc | EF7: 12 | EG7: A078-COG-X-BVM-T3Sc | EH7: 11 | EI7: A079-COG-X-BVM-T3Sc | EJ7: 11.5 | EK7: A080-COG-X-BVM-T3Sc | EL7: 11.5 | EM7: A081-COG-X-BVM-T3Sc | EN7: 12 | EO7: A082-COG-X-BVM-T3Sc | EP7: 12 | EQ7: A083-COG-X-BVM-T3Sc | ER7: 10 | ES7: A084-COG-X-BVM-T3Sc | ET7: 8.5 | EU7: A085-COG-X-BVM-T3Sc | EV7: 12 | EW7: A086-COG-X-BVM-T3Sc | EX7: 11.5 | EY7: A087-COG-X-BVM-T3Sc | EZ7: 12 | FA7: A088-COG-X-BVM-T3Sc | FB7: 12 | FC7: A089-COG-X-BVM-T3Sc | FD7: 12 | FE7: A090-COG-X-BVM-T3Sc | FF7: 11 | FG7: A091-COG-X-BVM-T3Sc | FH7: 11 | FI7: A092-COG-X-BVM-T3Sc | FJ7: 11 | FK7: A093-COG-X-BVM-T3Sc | FL7: 11 | FM7: A094-COG-X-BVM-T3Sc | FN7: 10.5 | FO7: A095-COG-X-BVM-T3Sc | FP7: 11.5 | FQ7: A096-COG-X-BVM-T3Sc | FR7: 11 | FS7: A097-COG-X-BVM-T3Sc | FT7: 7.5 | FU7: A098-COG-X-BVM-T3Sc | FV7: 11.5 | FW7: A099-COG-X-BVM-T3Sc | FX7: 11.5 | FY7: A100-COG-X-BVM-T3Sc | FZ7: 7 | GA7: A101-COG-X-BVM-T3Sc | GB7: 11.5 | GC7: A102-COG-X-BVM-T3Sc | GD7: 12 | GE7: A103-COG-X-BVM-T3Sc | GF7: 11 | GG7: A104-COG-X-BVM-T3Sc | GH7: 12 | GI7: A105-COG-X-BVM-T3Sc | GJ7: 8.5 | GK7: A106-COG-X-BVM-T3Sc | GL7: 12 | GM7: A107-COG-X-BVM-T3Sc | GN7: 8 | GO7: A108-COG-X-BVM-T3Sc | GP7: 11 | GQ7: A109-COG-X-BVM-T3Sc | GR7: 9.5
A8: A010-COG-X-BVM-TDTD | B8: 1320 | C8: A011-COG-X-BVM-TDTD | D8: 1500 | E8: A012-COG-X-BVM-TDTD | F8: 1500 | G8: A013-COG-X-BVM-TDTD | H8: 1200 | I8: A014-COG-X-BVM-TDTD | J8: 1388 | K8: A015-COG-X-BVM-TDTD | L8: 895 | M8: A016-COG-X-BVM-TDTD | N8: 911 | O8: A017-COG-X-BVM-TDTD | P8: 1200 | Q8: A018-COG-X-BVM-TDTD | R8: 1200 | S8: A019-COG-X-BVM-TDTD | T8: 1200 | U8: A020-COG-X-BVM-TDTD | V8: 1150 | W8: A021-COG-X-BVM-TDTD | X8: 1500 | Y8: A022-COG-X-BVM-TDTD | Z8: 931 | AA8: A023-COG-X-BVM-TDTD | AB8: 1260 | AC8: A024-COG-X-BVM-TDTD | AD8: 1080 | AE8: A025-COG-X-BVM-TDTD | AF8: 1320 | AG8: A026-COG-X-BVM-TDTD | AH8: 1200 | AI8: A027-COG-X-BVM-TDTD | AJ8: 1260 | AK8: A028-COG-X-BVM-TDTD | AL8: 1320 | AM8: A029-COG-X-BVM-TDTD | AN8: 1500 | AO8: A030-COG-X-BVM-TDTD | AP8: 1080 | AQ8: A031-COG-X-BVM-TDTD | AR8: 1500 | AS8: A032-COG-X-BVM-TDTD | AT8: 1560 | AU8: A033-COG-X-BVM-TDTD | AV8: 1200 | AW8: A034-COG-X-BVM-TDTD | AX8: 1200 | AY8: A035-COG-X-BVM-TDTD | AZ8: 1560 | BA8: A036-COG-X-BVM-TDTD | BB8: 1250 | BC8: A037-COG-X-BVM-TDTD | BD8: 1200 | BE8: A038-COG-X-BVM-TDTD | BF8: 1320 | BG8: A039-COG-X-BVM-TDTD | BH8: 1440 | BI8: A040-COG-X-BVM-TDTD | BJ8: 1200 | BK8: A041-COG-X-BVM-TDTD | BL8: 1500 | BM8: A042-COG-X-BVM-TDTD | BN8: 1320 | BO8: A043-COG-X-BVM-TDTD | BP8: 1200 | BQ8: A044-COG-X-BVM-TDTD | BR8: 1200 | BS8: A045-COG-X-BVM-TDTD | BT8: 1200 | BU8: A046-COG-X-BVM-TDTD | BV8: 1260 | BW8: A047-COG-X-BVM-TDTD | BX8: 1500 | BY8: A048-COG-X-BVM-TDTD | BZ8: 1500 | CA8: A049-COG-X-BVM-TDTD | CB8: 1260 | CC8: A050-COG-X-BVM-TDTD | CD8: 1080 | CE8: A051-COG-X-BVM-TDTD | CF8: 1620 | CG8: A052-COG-X-BVM-TDTD | CH8: 1140 | CI8: A053-COG-X-BVM-TDTD | CJ8: 1320 | CK8: A054-COG-X-BVM-TDTD | CL8: 1260 | CM8: A055-COG-X-BVM-TDTD | CN8: 1200 | CO8: A056-COG-X-BVM-TDTD | CP8: 1200 | CQ8: A057-COG-X-BVM-TDTD | CR8: 1440 | CS8: A058-COG-X-BVM-TDTD | CT8: 1380 | CU8: A059-COG-X-BVM-TDTD | CV8: 1620 | CW8: A060-COG-X-BVM-TDTD | CX8: 1260 | CY8: A061-COG-X-BVM-TDTD | CZ8: 1140 | DA8: A062-COG-X-BVM-TDTD | DB8: 1260 | DC8: A063-COG-X-BVM-TDTD | DD8: 1200 | DE8: A064-COG-X-BVM-TDTD | DF8: 1380 | DG8: A065-COG-X-BVM-TDTD | DH8: 1560 | DI8: A066-COG-X-BVM-TDTD | DJ8: 1080 | DK8: A067-COG-X-BVM-TDTD | DL8: 1020 | DM8: A068-COG-X-BVM-TDTD | DN8: 1140 | DO8: A069-COG-X-BVM-TDTD | DP8: 1440 | DQ8: A070-COG-X-BVM-TDTD | DR8: 1080 | DS8: A071-COG-X-BVM-TDTD | DT8: 1500 | DU8: A072-COG-X-BVM-TDTD | DV8: 1200 | DW8: A073-COG-X-BVM-TDTD | DX8: 1200 | DY8: A074-COG-X-BVM-TDTD | DZ8: 1200 | EA8: A075-COG-X-BVM-TDTD | EB8: 1260 | EC8: A076-COG-X-BVM-TDTD | ED8: 1500 | EE8: A077-COG-X-BVM-TDTD | EF8: 1500 | EG8: A078-COG-X-BVM-TDTD | EH8: 1080 | EI8: A079-COG-X-BVM-TDTD | EJ8: 1440 | EK8: A080-COG-X-BVM-TDTD | EL8: 1200 | EM8: A081-COG-X-BVM-TDTD | EN8: 1200 | EO8: A082-COG-X-BVM-TDTD | EP8: 1680 | EQ8: A083-COG-X-BVM-TDTD | ER8: 1200 | ES8: A084-COG-X-BVM-TDTD | ET8: 1980 | EU8: A085-COG-X-BVM-TDTD | EV8: 1500 | EW8: A086-COG-X-BVM-TDTD | EX8: 1260 | EY8: A087-COG-X-BVM-TDTD | EZ8: 1260 | FA8: A088-COG-X-BVM-TDTD | FB8: 1620 | FC8: A089-COG-X-BVM-TDTD | FD8: 1260 | FE8: A090-COG-X-BVM-TDTD | FF8: 1320 | FG8: A091-COG-X-BVM-TDTD | FH8: 1260 | FI8: A092-COG-X-BVM-TDTD | FJ8: 1320 | FK8: A093-COG-X-BVM-TDTD | FL8: 1620 | FM8: A094-COG-X-BVM-TDTD | FN8: 1200 | FO8: A095-COG-X-BVM-TDTD | FP8: 1320 | FQ8: A096-COG-X-BVM-TDTD | FR8: 2340 | FS8: A097-COG-X-BVM-TDTD | FT8: 1320 | FU8: A098-COG-X-BVM-TDTD | FV8: 1200 | FW8: A099-COG-X-BVM-TDTD | FX8: 1560 | FY8: A100-COG-X-BVM-TDTD | FZ8: 1500 | GA8: A101-COG-X-BVM-TDTD | GB8: 1500 | GC8: A102-COG-X-BVM-TDTD | GD8: 1620 | GE8: A103-COG-X-BVM-TDTD | GF8: 1500 | GG8: A104-COG-X-BVM-TDTD | GH8: 1200 | GI8: A105-COG-X-BVM-TDTD | GJ8: 1260 | GK8: A106-COG-X-BVM-TDTD | GL8: 1380 | GM8: A107-COG-X-BVM-TDTD | GN8: 1380 | GO8: A108-COG-X-BVM-TDTD | GP8: 1260 | GQ8: A109-COG-X-BVM-TDTD | GR8: 1320
A9: A010-COG-X-BVM-TDTi | B9: 53 | C9: A011-COG-X-BVM-TDTi | E9: A012-COG-X-BVM-TDTi | G9: A013-COG-X-BVM-TDTi | H9: 16 | I9: A014-COG-X-BVM-TDTi | J9: 28 | K9: A015-COG-X-BVM-TDTi | L9: 35 | M9: A016-COG-X-BVM-TDTi | N9: 22 | O9: A017-COG-X-BVM-TDTi | P9: 29 | Q9: A018-COG-X-BVM-TDTi | R9: 44 | S9: A019-COG-X-BVM-TDTi | T9: 22 | U9: A020-COG-X-BVM-TDTi | V9: 41 | W9: A021-COG-X-BVM-TDTi | X9: 19 | Y9: A022-COG-X-BVM-TDTi | Z9: 34 | AA9: A023-COG-X-BVM-TDTi | AB9: 1 | AC9: A024-COG-X-BVM-TDTi | AD9: 45 | AE9: A025-COG-X-BVM-TDTi | AF9: 62 | AG9: A026-COG-X-BVM-TDTi | AH9: 31 | AI9: A027-COG-X-BVM-TDTi | AJ9: 19 | AK9: A028-COG-X-BVM-TDTi | AL9: 20 | AM9: A029-COG-X-BVM-TDTi | AN9: 24 | AO9: A030-COG-X-BVM-TDTi | AP9: 20 | AQ9: A031-COG-X-BVM-TDTi | AR9: 20 | AS9: A032-COG-X-BVM-TDTi | AT9: 25 | AU9: A033-COG-X-BVM-TDTi | AV9: 23 | AW9: A034-COG-X-BVM-TDTi | AX9: 25 | AY9: A035-COG-X-BVM-TDTi | AZ9: 44 | BA9: A036-COG-X-BVM-TDTi | BB9: 58 | BC9: A037-COG-X-BVM-TDTi | BD9: 32 | BE9: A038-COG-X-BVM-TDTi | BF9: 48 | BG9: A039-COG-X-BVM-TDTi | BH9: 41 | BI9: A040-COG-X-BVM-TDTi | BJ9: 31 | BK9: A041-COG-X-BVM-TDTi | BL9: 30 | BM9: A042-COG-X-BVM-TDTi | BN9: 29 | BO9: A043-COG-X-BVM-TDTi | BP9: 29 | BQ9: A044-COG-X-BVM-TDTi | BR9: 27 | BS9: A045-COG-X-BVM-TDTi | BT9: 23 | BU9: A046-COG-X-BVM-TDTi | BV9: 28 | BW9: A047-COG-X-BVM-TDTi | BX9: 18 | BY9: A048-COG-X-BVM-TDTi | BZ9: 15 | CA9: A049-COG-X-BVM-TDTi | CB9: 35 | CC9: A050-COG-X-BVM-TDTi | CD9: 26 | CE9: A051-COG-X-BVM-TDTi | CF9: 31 | CG9: A052-COG-X-BVM-TDTi | CH9: 26 | CI9: A053-COG-X-BVM-TDTi | CJ9: 31 | CK9: A054-COG-X-BVM-TDTi | CL9: 21 | CM9: A055-COG-X-BVM-TDTi | CN9: 51 | CO9: A056-COG-X-BVM-TDTi | CP9: 38 | CQ9: A057-COG-X-BVM-TDTi | CR9: 21 | CS9: A058-COG-X-BVM-TDTi | CT9: 34 | CU9: A059-COG-X-BVM-TDTi | CV9: 40 | CW9: A060-COG-X-BVM-TDTi | CX9: 36 | CY9: A061-COG-X-BVM-TDTi | CZ9: 39 | DA9: A062-COG-X-BVM-TDTi | DB9: 22 | DC9: A063-COG-X-BVM-TDTi | DD9: 30 | DE9: A064-COG-X-BVM-TDTi | DF9: 15 | DG9: A065-COG-X-BVM-TDTi | DH9: 24 | DI9: A066-COG-X-BVM-TDTi | DJ9: 28 | DK9: A067-COG-X-BVM-TDTi | DL9: 26 | DM9: A068-COG-X-BVM-TDTi | DN9: 26 | DO9: A069-COG-X-BVM-TDTi | DP9: 36 | DQ9: A070-COG-X-BVM-TDTi | DR9: 20 | DS9: A071-COG-X-BVM-TDTi | DU9: A072-COG-X-BVM-TDTi | DV9: 25 | DW9: A073-COG-X-BVM-TDTi | DX9: 36 | DY9: A074-COG-X-BVM-TDTi | DZ9: 24 | EA9: A075-COG-X-BVM-TDTi | EB9: 23 | EC9: A076-COG-X-BVM-TDTi | ED9: 25 | EE9: A077-COG-X-BVM-TDTi | EF9: 30 | EG9: A078-COG-X-BVM-TDTi | EH9: 34 | EI9: A079-COG-X-BVM-TDTi | EJ9: 191 | EK9: A080-COG-X-BVM-TDTi | EL9: 25 | EM9: A081-COG-X-BVM-TDTi | EN9: 38 | EO9: A082-COG-X-BVM-TDTi | EP9: 33 | EQ9: A083-COG-X-BVM-TDTi | ER9: 21 | ES9: A084-COG-X-BVM-TDTi | ET9: 36 | EU9: A085-COG-X-BVM-TDTi | EV9: 23 | EW9: A086-COG-X-BVM-TDTi | EX9: 23 | EY9: A087-COG-X-BVM-TDTi | EZ9: 26 | FA9: A088-COG-X-BVM-TDTi | FB9: 30 | FC9: A089-COG-X-BVM-TDTi | FD9: 26 | FE9: A090-COG-X-BVM-TDTi | FF9: 30 | FG9: A091-COG-X-BVM-TDTi | FH9: 22 | FI9: A092-COG-X-BVM-TDTi | FJ9: 61 | FK9: A093-COG-X-BVM-TDTi | FL9: 35 | FM9: A094-COG-X-BVM-TDTi | FN9: 52 | FO9: A095-COG-X-BVM-TDTi | FP9: 30 | FQ9: A096-COG-X-BVM-TDTi | FR9: 103 | FS9: A097-COG-X-BVM-TDTi | FT9: 32 | FU9: A098-COG-X-BVM-TDTi | FV9: 25 | FW9: A099-COG-X-BVM-TDTi | FX9: 76 | FY9: A100-COG-X-BVM-TDTi | FZ9: 24 | GA9: A101-COG-X-BVM-TDTi | GB9: 64 | GC9: A102-COG-X-BVM-TDTi | GD9: 29 | GE9: A103-COG-X-BVM-TDTi | GF9: 58 | GG9: A104-COG-X-BVM-TDTi | GH9: 69 | GI9: A105-COG-X-BVM-TDTi | GJ9: 42 | GK9: A106-COG-X-BVM-TDTi | GL9: 68 | GM9: A107-COG-X-BVM-TDTi | GN9: 41 | GO9: A108-COG-X-BVM-TDTi | GP9: 31 | GQ9: A109-COG-X-BVM-TDTi | GR9: 63
A10: A010-COG-X-BVM-TDSc | B10: 12 | C10: A011-COG-X-BVM-TDSc | D10: 12 | E10: A012-COG-X-BVM-TDSc | F10: 12 | G10: A013-COG-X-BVM-TDSc | H10: 11.5 | I10: A014-COG-X-BVM-TDSc | J10: 12 | K10: A015-COG-X-BVM-TDSc | L10: 12 | M10: A016-COG-X-BVM-TDSc | N10: 12 | O10: A017-COG-X-BVM-TDSc | P10: 12 | Q10: A018-COG-X-BVM-TDSc | R10: 8 | S10: A019-COG-X-BVM-TDSc | T10: 11.5 | U10: A020-COG-X-BVM-TDSc | V10: 12 | W10: A021-COG-X-BVM-TDSc | X10: 12 | Y10: A022-COG-X-BVM-TDSc | Z10: 12 | AA10: A023-COG-X-BVM-TDSc | AB10: 10.5 | AC10: A024-COG-X-BVM-TDSc | AD10: 11.5 | AE10: A025-COG-X-BVM-TDSc | AF10: 12 | AG10: A026-COG-X-BVM-TDSc | AH10: 12 | AI10: A027-COG-X-BVM-TDSc | AJ10: 11.5 | AK10: A028-COG-X-BVM-TDSc | AL10: 11.5 | AM10: A029-COG-X-BVM-TDSc | AN10: 12 | AO10: A030-COG-X-BVM-TDSc | AP10: 12 | AQ10: A031-COG-X-BVM-TDSc | AR10: 12 | AS10: A032-COG-X-BVM-TDSc | AT10: 12 | AU10: A033-COG-X-BVM-TDSc | AV10: 12 | AW10: A034-COG-X-BVM-TDSc | AX10: 12 | AY10: A035-COG-X-BVM-TDSc | AZ10: 12 | BA10: A036-COG-X-BVM-TDSc | BB10: 12 | BC10: A037-COG-X-BVM-TDSc | BD10: 12 | BE10: A038-COG-X-BVM-TDSc | BF10: 10 | BG10: A039-COG-X-BVM-TDSc | BH10: 12 | BI10: A040-COG-X-BVM-TDSc | BJ10: 9 | BK10: A041-COG-X-BVM-TDSc | BL10: 12 | BM10: A042-COG-X-BVM-TDSc | BN10: 12 | BO10: A043-COG-X-BVM-TDSc | BP10: 12 | BQ10: A044-COG-X-BVM-TDSc | BR10: 12 | BS10: A045-COG-X-BVM-TDSc | BT10: 11 | BU10: A046-COG-X-BVM-TDSc | BV10: 12 | BW10: A047-COG-X-BVM-TDSc | BX10: 7 | BY10: A048-COG-X-BVM-TDSc | BZ10: 12 | CA10: A049-COG-X-BVM-TDSc | CB10: 12 | CC10: A050-COG-X-BVM-TDSc | CD10: 12 | CE10: A051-COG-X-BVM-TDSc | CF10: 11.5 | CG10: A052-COG-X-BVM-TDSc | CH10: 12 | CI10: A053-COG-X-BVM-TDSc | CJ10: 11.5 | CK10: A054-COG-X-BVM-TDSc | CL10: 12 | CM10: A055-COG-X-BVM-TDSc | CN10: 11 | CO10: A056-COG-X-BVM-TDSc | CP10: 12 | CQ10: A057-COG-X-BVM-TDSc | CR10: 12 | CS10: A058-COG-X-BVM-TDSc | CT10: 12 | CU10: A059-COG-X-BVM-TDSc | CV10: 12 | CW10: A060-COG-X-BVM-TDSc | CX10: 11.5 | CY10: A061-COG-X-BVM-TDSc | CZ10: 11.5 | DA10: A062-COG-X-BVM-TDSc | DB10: 12 | DC10: A063-COG-X-BVM-TDSc | DD10: 11.5 | DE10: A064-COG-X-BVM-TDSc | DF10: 12 | DG10: A065-COG-X-BVM-TDSc | DH10: 8.5 | DI10: A066-COG-X-BVM-TDSc | DJ10: 10.5 | DK10: A067-COG-X-BVM-TDSc | DL10: 11 | DM10: A068-COG-X-BVM-TDSc | DN10: 12 | DO10: A069-COG-X-BVM-TDSc | DP10: 11.5 | DQ10: A070-COG-X-BVM-TDSc | DR10: 11.5 | DS10: A071-COG-X-BVM-TDSc | DT10: 12 | DU10: A072-COG-X-BVM-TDSc | DV10: 12 | DW10: A073-COG-X-BVM-TDSc | DX10: 10 | DY10: A074-COG-X-BVM-TDSc | DZ10: 12 | EA10: A075-COG-X-BVM-TDSc | EB10: 11.5 | EC10: A076-COG-X-BVM-TDSc | ED10: 7 | EE10: A077-COG-X-BVM-TDSc | EF10: 12 | EG10: A078-COG-X-BVM-TDSc | EH10: 11 | EI10: A079-COG-X-BVM-TDSc | EJ10: 8 | EK10: A080-COG-X-BVM-TDSc | EL10: 11.5 | EM10: A081-COG-X-BVM-TDSc | EN10: 12 | EO10: A082-COG-X-BVM-TDSc | EP10: 11.5 | EQ10: A083-COG-X-BVM-TDSc | ER10: 10 | ES10: A084-COG-X-BVM-TDSc | ET10: 7 | EU10: A085-COG-X-BVM-TDSc | EV10: 12 | EW10: A086-COG-X-BVM-TDSc | EX10: 11.5 | EY10: A087-COG-X-BVM-TDSc | EZ10: 11.5 | FA10: A088-COG-X-BVM-TDSc | FB10: 10 | FC10: A089-COG-X-BVM-TDSc | FD10: 12 | FE10: A090-COG-X-BVM-TDSc | FF10: 11 | FG10: A091-COG-X-BVM-TDSc | FH10: 11 | FI10: A092-COG-X-BVM-TDSc | FJ10: 11 | FK10: A093-COG-X-BVM-TDSc | FL10: 10.5 | FM10: A094-COG-X-BVM-TDSc | FN10: 10 | FO10: A095-COG-X-BVM-TDSc | FP10: 11.5 | FQ10: A096-COG-X-BVM-TDSc | FR10: 7.5 | FS10: A097-COG-X-BVM-TDSc | FT10: 8 | FU10: A098-COG-X-BVM-TDSc | FV10: 11 | FW10: A099-COG-X-BVM-TDSc | FX10: 11 | FY10: A100-COG-X-BVM-TDSc | FZ10: 5 | GA10: A101-COG-X-BVM-TDSc | GB10: 8.5 | GC10: A102-COG-X-BVM-TDSc | GD10: 12 | GE10: A103-COG-X-BVM-TDSc | GF10: 10.5 | GG10: A104-COG-X-BVM-TDSc | GH10: 12 | GI10: A105-COG-X-BVM-TDSc | GJ10: 8.5 | GK10: A106-COG-X-BVM-TDSc | GL10: 12 | GM10: A107-COG-X-BVM-TDSc | GN10: 8.5 | GO10: A108-COG-X-BVM-TDSc | GP10: 11.5 | GQ10: A109-COG-X-BVM-TDSc | GR10: 5.5
A11: A010-COG-X-BVM-Re01 | B11: y | C11: A011-COG-X-BVM-Re01 | D11: y | E11: A012-COG-X-BVM-Re01 | F11: y | G11: A013-COG-X-BVM-Re01 | H11: n | I11: A014-COG-X-BVM-Re01 | J11: y | K11: A015-COG-X-BVM-Re01 | L11: y | M11: A016-COG-X-BVM-Re01 | N11: y | O11: A017-COG-X-BVM-Re01 | P11: y | Q11: A018-COG-X-BVM-Re01 | R11: y | S11: A019-COG-X-BVM-Re01 | T11: y | U11: A020-COG-X-BVM-Re01 | V11: y | W11: A021-COG-X-BVM-Re01 | X11: y | Y11: A022-COG-X-BVM-Re01 | Z11: y | AA11: A023-COG-X-BVM-Re01 | AB11: y | AC11: A024-COG-X-BVM-Re01 | AD11: y | AE11: A025-COG-X-BVM-Re01 | AF11: y | AG11: A026-COG-X-BVM-Re01 | AH11: y | AI11: A027-COG-X-BVM-Re01 | AJ11: y | AK11: A028-COG-X-BVM-Re01 | AL11: y | AM11: A029-COG-X-BVM-Re01 | AN11: y | AO11: A030-COG-X-BVM-Re01 | AP11: y | AQ11: A031-COG-X-BVM-Re01 | AR11: y | AS11: A032-COG-X-BVM-Re01 | AT11: y | AU11: A033-COG-X-BVM-Re01 | AV11: y | AW11: A034-COG-X-BVM-Re01 | AX11: y | AY11: A035-COG-X-BVM-Re01 | AZ11: y | BA11: A036-COG-X-BVM-Re01 | BB11: y | BC11: A037-COG-X-BVM-Re01 | BD11: y | BE11: A038-COG-X-BVM-Re01 | BF11: y | BG11: A039-COG-X-BVM-Re01 | BH11: y | BI11: A040-COG-X-BVM-Re01 | BJ11: y | BK11: A041-COG-X-BVM-Re01 | BL11: y | BM11: A042-COG-X-BVM-Re01 | BN11: y | BO11: A043-COG-X-BVM-Re01 | BP11: y | BQ11: A044-COG-X-BVM-Re01 | BR11: y | BS11: A045-COG-X-BVM-Re01 | BT11: y | BU11: A046-COG-X-BVM-Re01 | BV11: y | BW11: A047-COG-X-BVM-Re01 | BX11: y | BY11: A048-COG-X-BVM-Re01 | BZ11: y | CA11: A049-COG-X-BVM-Re01 | CB11: y | CC11: A050-COG-X-BVM-Re01 | CD11: y | CE11: A051-COG-X-BVM-Re01 | CF11: n | CG11: A052-COG-X-BVM-Re01 | CH11: y | CI11: A053-COG-X-BVM-Re01 | CJ11: y | CK11: A054-COG-X-BVM-Re01 | CL11: y | CM11: A055-COG-X-BVM-Re01 | CN11: y | CO11: A056-COG-X-BVM-Re01 | CP11: y | CQ11: A057-COG-X-BVM-Re01 | CR11: y | CS11: A058-COG-X-BVM-Re01 | CT11: y | CU11: A059-COG-X-BVM-Re01 | CV11: y | CW11: A060-COG-X-BVM-Re01 | CX11: y | CY11: A061-COG-X-BVM-Re01 | CZ11: y | DA11: A062-COG-X-BVM-Re01 | DB11: y | DC11: A063-COG-X-BVM-Re01 | DD11: y | DE11: A064-COG-X-BVM-Re01 | DF11: y | DG11: A065-COG-X-BVM-Re01 | DH11: y | DI11: A066-COG-X-BVM-Re01 | DJ11: y | DK11: A067-COG-X-BVM-Re01 | DL11: y | DM11: A068-COG-X-BVM-Re01 | DN11: y | DO11: A069-COG-X-BVM-Re01 | DP11: y | DQ11: A070-COG-X-BVM-Re01 | DR11: y | DS11: A071-COG-X-BVM-Re01 | DT11: y | DU11: A072-COG-X-BVM-Re01 | DV11: y | DW11: A073-COG-X-BVM-Re01 | DX11: y | DY11: A074-COG-X-BVM-Re01 | DZ11: y | EA11: A075-COG-X-BVM-Re01 | EB11: y | EC11: A076-COG-X-BVM-Re01 | ED11: y | EE11: A077-COG-X-BVM-Re01 | EF11: y | EG11: A078-COG-X-BVM-Re01 | EH11: y | EI11: A079-COG-X-BVM-Re01 | EJ11: y | EK11: A080-COG-X-BVM-Re01 | EL11: y | EM11: A081-COG-X-BVM-Re01 | EN11: n | EO11: A082-COG-X-BVM-Re01 | EP11: y | EQ11: A083-COG-X-BVM-Re01 | ER11: y | ES11: A084-COG-X-BVM-Re01 | ET11: y | EU11: A085-COG-X-BVM-Re01 | EV11: y | EW11: A086-COG-X-BVM-Re01 | EX11: y | EY11: A087-COG-X-BVM-Re01 | EZ11: y | FA11: A088-COG-X-BVM-Re01 | FB11: y | FC11: A089-COG-X-BVM-Re01 | FD11: y | FE11: A090-COG-X-BVM-Re01 | FF11: y | FG11: A091-COG-X-BVM-Re01 | FH11: y | FI11: A092-COG-X-BVM-Re01 | FJ11: y | FK11: A093-COG-X-BVM-Re01 | FL11: y | FM11: A094-COG-X-BVM-Re01 | FN11: y | FO11: A095-COG-X-BVM-Re01 | FP11: y | FQ11: A096-COG-X-BVM-Re01 | FR11: y | FS11: A097-COG-X-BVM-Re01 | FT11: n | FU11: A098-COG-X-BVM-Re01 | FV11: y | FW11: A099-COG-X-BVM-Re01 | FX11: y | FY11: A100-COG-X-BVM-Re01 | FZ11: y | GA11: A101-COG-X-BVM-Re01 | GB11: y | GC11: A102-COG-X-BVM-Re01 | GD11: y | GE11: A103-COG-X-BVM-Re01 | GF11: y | GG11: A104-COG-X-BVM-Re01 | GH11: y | GI11: A105-COG-X-BVM-Re01 | GJ11: y | GK11: A106-COG-X-BVM-Re01 | GL11: y | GM11: A107-COG-X-BVM-Re01 | GN11: y | GO11: A108-COG-X-BVM-Re01 | GP11: y | GQ11: A109-COG-X-BVM-Re01 | GR11: y
A12: A010-COG-X-BVM-Re02 | B12: n | C12: A011-COG-X-BVM-Re02 | D12: n | E12: A012-COG-X-BVM-Re02 | F12: n | G12: A013-COG-X-BVM-Re02 | H12: n | I12: A014-COG-X-BVM-Re02 | J12: n | K12: A015-COG-X-BVM-Re02 | L12: n | M12: A016-COG-X-BVM-Re02 | N12: n | O12: A017-COG-X-BVM-Re02 | P12: n | Q12: A018-COG-X-BVM-Re02 | R12: n | S12: A019-COG-X-BVM-Re02 | T12: n | U12: A020-COG-X-BVM-Re02 | V12: n | W12: A021-COG-X-BVM-Re02 | X12: n | Y12: A022-COG-X-BVM-Re02 | Z12: n | AA12: A023-COG-X-BVM-Re02 | AB12: n | AC12: A024-COG-X-BVM-Re02 | AD12: n | AE12: A025-COG-X-BVM-Re02 | AF12: n | AG12: A026-COG-X-BVM-Re02 | AH12: n | AI12: A027-COG-X-BVM-Re02 | AJ12: n | AK12: A028-COG-X-BVM-Re02 | AL12: n | AM12: A029-COG-X-BVM-Re02 | AN12: n | AO12: A030-COG-X-BVM-Re02 | AP12: n | AQ12: A031-COG-X-BVM-Re02 | AR12: n | AS12: A032-COG-X-BVM-Re02 | AT12: n | AU12: A033-COG-X-BVM-Re02 | AV12: n | AW12: A034-COG-X-BVM-Re02 | AX12: n | AY12: A035-COG-X-BVM-Re02 | AZ12: n | BA12: A036-COG-X-BVM-Re02 | BB12: n | BC12: A037-COG-X-BVM-Re02 | BD12: n | BE12: A038-COG-X-BVM-Re02 | BF12: n | BG12: A039-COG-X-BVM-Re02 | BH12: n | BI12: A040-COG-X-BVM-Re02 | BJ12: n | BK12: A041-COG-X-BVM-Re02 | BL12: n | BM12: A042-COG-X-BVM-Re02 | BN12: n | BO12: A043-COG-X-BVM-Re02 | BP12: n | BQ12: A044-COG-X-BVM-Re02 | BR12: n | BS12: A045-COG-X-BVM-Re02 | BT12: n | BU12: A046-COG-X-BVM-Re02 | BV12: n | BW12: A047-COG-X-BVM-Re02 | BX12: n | BY12: A048-COG-X-BVM-Re02 | BZ12: n | CA12: A049-COG-X-BVM-Re02 | CB12: n | CC12: A050-COG-X-BVM-Re02 | CD12: n | CE12: A051-COG-X-BVM-Re02 | CF12: n | CG12: A052-COG-X-BVM-Re02 | CH12: n | CI12: A053-COG-X-BVM-Re02 | CJ12: n | CK12: A054-COG-X-BVM-Re02 | CL12: n | CM12: A055-COG-X-BVM-Re02 | CN12: n | CO12: A056-COG-X-BVM-Re02 | CP12: n | CQ12: A057-COG-X-BVM-Re02 | CR12: n | CS12: A058-COG-X-BVM-Re02 | CT12: n | CU12: A059-COG-X-BVM-Re02 | CV12: n | CW12: A060-COG-X-BVM-Re02 | CX12: n | CY12: A061-COG-X-BVM-Re02 | CZ12: n | DA12: A062-COG-X-BVM-Re02 | DB12: n | DC12: A063-COG-X-BVM-Re02 | DD12: n | DE12: A064-COG-X-BVM-Re02 | DF12: n | DG12: A065-COG-X-BVM-Re02 | DH12: n | DI12: A066-COG-X-BVM-Re02 | DJ12: n | DK12: A067-COG-X-BVM-Re02 | DL12: n | DM12: A068-COG-X-BVM-Re02 | DN12: n | DO12: A069-COG-X-BVM-Re02 | DP12: n | DQ12: A070-COG-X-BVM-Re02 | DR12: n | DS12: A071-COG-X-BVM-Re02 | DT12: n | DU12: A072-COG-X-BVM-Re02 | DV12: n | DW12: A073-COG-X-BVM-Re02 | DX12: n | DY12: A074-COG-X-BVM-Re02 | DZ12: n | EA12: A075-COG-X-BVM-Re02 | EB12: n | EC12: A076-COG-X-BVM-Re02 | ED12: n | EE12: A077-COG-X-BVM-Re02 | EF12: n | EG12: A078-COG-X-BVM-Re02 | EH12: n | EI12: A079-COG-X-BVM-Re02 | EJ12: n | EK12: A080-COG-X-BVM-Re02 | EL12: n | EM12: A081-COG-X-BVM-Re02 | EN12: n | EO12: A082-COG-X-BVM-Re02 | EP12: n | EQ12: A083-COG-X-BVM-Re02 | ER12: n | ES12: A084-COG-X-BVM-Re02 | ET12: n | EU12: A085-COG-X-BVM-Re02 | EV12: n | EW12: A086-COG-X-BVM-Re02 | EX12: n | EY12: A087-COG-X-BVM-Re02 | EZ12: n | FA12: A088-COG-X-BVM-Re02 | FB12: n | FC12: A089-COG-X-BVM-Re02 | FD12: n | FE12: A090-COG-X-BVM-Re02 | FF12: n | FG12: A091-COG-X-BVM-Re02 | FH12: n | FI12: A092-COG-X-BVM-Re02 | FJ12: n | FK12: A093-COG-X-BVM-Re02 | FL12: n | FM12: A094-COG-X-BVM-Re02 | FN12: n | FO12: A095-COG-X-BVM-Re02 | FP12: n | FQ12: A096-COG-X-BVM-Re02 | FR12: n | FS12: A097-COG-X-BVM-Re02 | FT12: n | FU12: A098-COG-X-BVM-Re02 | FV12: n | FW12: A099-COG-X-BVM-Re02 | FX12: n | FY12: A100-COG-X-BVM-Re02 | FZ12: n | GA12: A101-COG-X-BVM-Re02 | GB12: n | GC12: A102-COG-X-BVM-Re02 | GD12: n | GE12: A103-COG-X-BVM-Re02 | GF12: n | GG12: A104-COG-X-BVM-Re02 | GH12: n | GI12: A105-COG-X-BVM-Re02 | GJ12: n | GK12: A106-COG-X-BVM-Re02 | GL12: n | GM12: A107-COG-X-BVM-Re02 | GN12: n | GO12: A108-COG-X-BVM-Re02 | GP12: n | GQ12: A109-COG-X-BVM-Re02 | GR12: n
