Workbook

Sheet output
A1: age_low | B1: age_high | C1: variable | D1: norm_m | E1: norm_sd | F1: norm_n | G1: data_m | H1: data_sd | I1: data_n | J1: t | K1: p | L1: x
A2: 18 | B2: 22 | C2: age | D2: 19.14 | E2: 1.22 | F2: 178 | G2: 21.285714 | H2: 0.75592895 | I2: 7 | J2: 7.1526015 | K2: 0.00015241793 | L2: 6.782054
A3: 18 | B3: 22 | C3: BVMT_t1 | D3: 7.49 | E3: 2.04 | F3: 178 | G3: 9.7142857 | H3: 1.7043362 | I3: 7 | J3: 3.3595582 | K3: 0.012923106 | L3: 2.0695165
A4: 18 | B4: 22 | C4: BVMT_t2 | D4: 10.14 | E4: 1.74 | F4: 178 | G4: 11.428571 | H4: 0.88640526 | I4: 7 | J4: 3.5841542 | K4: 0.0072193945 | L4: 1.6055142
A5: 18 | B5: 22 | C5: BVMT_t3 | D5: 11.1 | E5: 1.16 | F5: 178 | G5: 11.857143 | H5: 0.24397502 | I5: 7 | J5: 5.9739991 | K5: 6.4554659e-06 | L5: 3.4419677
A6: 18 | B6: 22 | C6: BVMT_total_recall | D6: 28.74 | E6: 4.32 | F6: 178 | G6: 33 | H6: 2.5819889 | I6: 7 | J6: 4.1431027 | K6: 0.0038489112 | L6: 2.4066194
A7: 18 | B7: 22 | C7: BVMT_learning | D7: 3.63 | E7: 1.67 | F7: 178 | G7: 2.1428571 | H7: 1.5468863 | I7: 7 | J7: -2.4872063 | K7: 0.043981684 | L7: -1.2109953
A8: 18 | B8: 22 | C8: BVMT_delayed_recall | D8: 10.79 | E8: 1.37 | F8: 178 | G8: 11.857143 | H8: 0.24397502 | I8: 7 | J8: 7.7321512 | K8: 1.7359055e-08 | L8: 6.1432167
A9: 18 | B9: 22 | C9: BVMT_percent_retained | D9: 95.34 | E9: 6.6 | F9: 178 | G9: 100 | H9: 0 | I9: 7 | J9: 9.4200234 | K9: 2.4686153e-17 | L9: 11.923023
A10: 18 | B10: 22 | C10: BVMT_hits | D10: 5.93 | E10: 0.28 | F10: 178 | G10: 5.7142857 | H10: 0.48795004 | I10: 7 | J10: -1.1621408 | K10: 0.28824216 | L10: -0.40296865
A11: 18 | B11: 22 | C11: BVMT_false_alarms | D11: 0.02 | E11: 0.14 | F11: 178 | G11: 0 | H11: 0 | I11: 7 | J11: -1.905952 | K11: 0.058277042 | L11: -0.1793217
A12: 18 | B12: 22 | C12: BVMT_discrimination_index | D12: 5.91 | E12: 0.31 | F12: 178 | G12: 5.7142857 | H12: 0.48795004 | I12: 7 | J12: -1.0528744 | K12: 0.33174098 | L12: -0.29546468
A13: 18 | B13: 22 | C13: BVMT_response_bias | D13: 0.49 | E13: 0.07 | F13: 178 | G13: 0.42857143 | H13: 0.12198751 | I13: 7 | J13: -1.323763 | K13: 0.23261244 | L13: -0.53813283
... A34: 22 | B34: 26 | C34: BVMT_hits | D34: 5.91 | E34: 0.28 | F34: 47 | G34: 5.9090909 | H34: 0.30151134 | I34: 11 | J34: -0.0091217251 | K34: 0.9928479 | L34: -9.979855e-06
A35: 22 | B35: 26 | C35: BVMT_false_alarms | D35: 0 | E35: 0 | F35: 47 | G35: 0 | H35: 0 | I35: 11
A36: 22 | B36: 26 | C36: BVMT_discrimination_index | D36: 5.91 | E36: 0.28 | F36: 47 | G36: 5.9090909 | H36: 0.30151134 | I36: 11 | J36: -0.0091217251 | K36: 0.9928479 | L36: -9.979855e-06
A37: 22 | B37: 26 | C37: BVMT_response_bias | D37: 0.47 | E37: 0.07 | F37: 47 | G37: 0.47727273 | H37: 0.075377836 | I37: 11 | J37: 0.2918952 | K37: 0.77455356 | L37: 0.011366335
A38: 24 | B38: 28 | C38: age | D38: 25.48 | E38: 1.09 | F38: 39 | G38: 26.333333 | H38: 1.4142136 | I38: 9 | J38: 1.6975706 | K38: 0.1195418 | L38: 0.68275403
A39: 24 | B39: 28 | C39: BVMT_t1 | D39: 7.19 | E39: 2.04 | F39: 39 | G39: 9.0555556 | H39: 2.2282903 | I39: 9 | J39: 2.2991195 | K39: 0.041501215 | L39: 1.2430646
A40: 24 | B40: 28 | C40: BVMT_t2 | D40: 9.82 | E40: 1.79 | F40: 39 | G40: 11.111111 | H40: 1.1395662 | I40: 9 | J40: 2.7131936 | K40: 0.01403706 | L40: 1.4113293
A41: 24 | B41: 28 | C41: BVMT_t3 | D41: 10.81 | E41: 1.28 | F41: 39 | G41: 11.833333 | H41: 0.5 | I41: 9 | J41: 3.8737058 | K41: 0.00046303038 | L41: 2.8869871
A42: 24 | B42: 28 | C42: BVMT_total_recall | D42: 27.83 | E42: 4.48 | F42: 39 | G42: 32 | H42: 3.6571847 | I42: 9 | J42: 2.9480923 | K42: 0.010491736 | L42: 1.8980853
A43: 24 | B43: 28 | C43: BVMT_learning | D43: 3.65 | E43: 1.69 | F43: 39 | G43: 2.7777778 | H43: 1.9220938 | I43: 9 | J43: -1.2540848 | K43: 0.23572604 | L43: -0.3159416
A44: 24 | B44: 28 | C44: BVMT_delayed_recall | D44: 10.46 | E44: 1.48 | F44: 39 | G44: 11.722222 | H44: 0.50689688 | I44: 9 | J44: 4.3367017 | K44: 9.9518423e-05 | L44: 3.709807
A45: 24 | B45: 28 | C45: BVMT_percent_retained | D45: 95.08 | E45: 8.04 | F45: 39 | G45: 99.074074 | H45: 1.8373273 | I45: 9 | J45: 2.8015227 | K45: 0.0074183691 | L45: 1.1576827
A46: 24 | B46: 28 | C46: BVMT_hits | D46: 5.89 | E46: 0.3 | F46: 39 | G46: 6 | H46: 0 | I46: 9 | J46: 2.2898326 | K46: 0.027674022 | L46: 0.62850083
A47: 24 | B47: 28 | C47: BVMT_false_alarms | D47: 0 | E47: 0 | F47: 39 | G47: 0 | H47: 0 | I47: 9
A48: 24 | B48: 28 | C48: BVMT_discrimination_index | D48: 5.89 | E48: 0.3 | F48: 39 | G48: 6 | H48: 0 | I48: 9 | J48: 2.2898326 | K48: 0.027674022 | L48: 0.62850083
A49: 24 | B49: 28 | C49: BVMT_response_bias | D49: 0.47 | E49: 0.07 | F49: 39 | G49: 0.5 | H49: 0 | I49: 9 | J49: 2.6764277 | K49: 0.010921857 | L49: 0.9250042
A50: 26 | B50: 30 | C50: age | D50: 28.45 | E50: 1.62 | F50: 42 | G50: 27.6 | H50: 1.5055453 | I50: 10 | J50: -1.5807222 | K50: 0.13564336 | L50: -0.46091256
A51: 26 | B51: 30 | C51: BVMT_t1 | D51: 7.09 | E51: 2.03 | F51: 42 | G51: 8.4 | H51: 2.2705848 | I51: 10 | J51: 1.6722572 | K51: 0.11900669 | L51: 0.58351266
A52: 26 | B52: 30 | C52: BVMT_t2 | D52: 9.72 | E52: 1.8 | F52: 42 | G52: 10.6 | H52: 1.4102797 | I52: 10 | J52: 1.674955 | K52: 0.11247504 | L52: 0.48094336
A53: 26 | B53: 30 | C53: BVMT_t3 | D53: 10.71 | E53: 1.32 | F53: 42 | G53: 11.85 | H53: 0.47434165 | I53: 10 | J53: 4.5067487 | K53: 5.2523137e-05 | L53: 4.0249689
A54: 26 | B54: 30 | C54: BVMT_total_recall | D54: 27.52 | E54: 4.54 | F54: 42 | G54: 30.85 | H54: 3.4322814 | I54: 10 | J54: 2.5777515 | K54: 0.019313784 | L54: 1.3087613
A55: 26 | B55: 30 | C55: BVMT_learning | D55: 3.66 | E55: 1.7 | F55: 42 | G55: 3.45 | H55: 2.060879 | I55: 10 | J55: -0.29892466 | K55: 0.77007652 | L55: -0.013459075
A56: 26 | B56: 30 | C56: BVMT_delayed_recall | D56: 10.35 | E56: 1.52 | F56: 42 | G56: 11.7 | H56: 0.48304589 | I56: 10 | J56: 4.8231866 | K56: 1.6064265e-05 | L56: 4.6508519
A57: 26 | B57: 30 | C57: BVMT_percent_retained | D57: 96.67 | E57: 6.31 | F57: 42 | G57: 98.75 | H57: 2.0126912 | I57: 10 | J57: 1.7881304 | K57: 0.080401023 | L57: 0.3941315
A58: 26 | B58: 30 | C58: BVMT_hits | D58: 5.97 | E58: 0.15 | F58: 42 | G58: 5.9 | H58: 0.31622777 | I58: 10 | J58: -0.68197122 | K58: 0.51076779 | L58: -0.10697926
A59: 26 | B59: 30 | C59: BVMT_false_alarms | D59: 0 | E59: 0 | F59: 42 | G59: 0 | H59: 0 | I59: 10
A60: 26 | B60: 30 | C60: BVMT_discrimination_index | D60: 5.97 | E60: 0.15 | F60: 42 | G60: 5.9 | H60: 0.31622777 | I60: 10 | J60: -0.68197122 | K60: 0.51076779 | L60: -0.10697926
...

Sheet clean
B1: Group | C1: age | D1: BVMT_t1 | E1: BVMT_t2 | F1: BVMT_t3 | G1: BVMT_total_recall | H1: BVMT_learning | I1: BVMT_delayed_recall | J1: BVMT_percent_retained | K1: BVMT_hits | L1: BVMT_false_alarms | M1: BVMT_discrimination_index | N1: BVMT_response_bias | P1: age | Q1: BVMT_t1 | R1: BVMT_t2 | S1: BVMT_t3 | T1: BVMT_total_recall | U1: BVMT_learning | V1: BVMT_delayed_recall | W1: BVMT_percent_retained | X1: BVMT_hits | Y1: BVMT_false_alarms | Z1: BVMT_discrimination_index | AA1: BVMT_response_bias
A2: 0 | B2: 18-22 | C2: {=ROUND(TRANSPOSE(INDIRECT("output!L"&$A2+2&":L"&$A2+13)),2)} -> 6.78 | D2: 2.07 | E2: 1.61 | F2: 3.44 | G2: 2.41 | H2: -1.21 | I2: 6.14 | J2: 11.92 | K2: -0.4 | L2: -0.18 | M2: -0.3 | N2: -0.54 | P2: {=ROUND(TRANSPOSE(INDIRECT("output!K"&$A2+2&":K"&$A2+13)),2)} -> 0 | Q2: 0.01 | R2: 0.01 | S2: 0 | T2: 0 | U2: 0.04 | V2: 0 | W2: 0 | X2: 0.29 | Y2: 0.06 | Z2: 0.33 | AA2: 0.23
A3: =A2+12 -> 12 | B3: 20-24 | C3: {=ROUND(TRANSPOSE(INDIRECT("output!L"&$A3+2&":L"&$A3+13)),2)} -> 0.5 | D3: 2.6 | E3: 3.78 | F3: 5.08 | G3: 4.59 | H3: -0.94 | I3: 0.65 | J3: 0.05 | K3: -0.32 | L3: -0.15 | M3: -0.17 | N3: -0.34 | P3: {=ROUND(TRANSPOSE(INDIRECT("output!K"&$A3+2&":K"&$A3+13)),2)} -> 0.12 | Q3: 0 | R3: 0 | S3: 0 | T3: 0 | U3: 0.04 | V3: 0.08 | W3: 0.63 | X3: 0.3 | Y3: 0.16 | Z3: 0.4 | AA3: 0.27
A4: =A3+12 -> 24 | B4: 22-26 | C4: {=ROUND(TRANSPOSE(INDIRECT("output!L"&$A4+2&":L"&$A4+13)),2)} -> -0.02 | D4: 1.61 | E4: 2.27 | F4: 2.86 | G4: 2.55 | H4: -0.51 | I4: 0.71 | J4: 0.01 | K4: 0 | L4: 0 | M4: 0 | N4: 0.01 | P4: {=ROUND(TRANSPOSE(INDIRECT("output!K"&$A4+2&":K"&$A4+13)),2)} -> 0.73 | Q4: 0.02 | R4: 0 | S4: 0 | T4: 0 | U4: 0.12 | V4: 0.06 | W4: 0.8 | X4: 0.99 | Y4: 0 | Z4: 0.99 | AA4: 0.77
A5: =A4+12 -> 36 | B5: 24-28 | C5: {=ROUND(TRANSPOSE(INDIRECT("output!L"&$A5+2&":L"&$A5+13)),2)} -> 0.68 | D5: 1.24 | E5: 1.41 | F5: 2.89 | G5: 1.9 | H5: -0.32 | I5: 3.71 | J5: 1.16 | K5: 0.63 | L5: 0 | M5: 0.63 | N5: 0.93 | P5: {=ROUND(TRANSPOSE(INDIRECT("output!K"&$A5+2&":K"&$A5+13)),2)} -> 0.12 | Q5: 0.04 | R5: 0.01 | S5: 0 | T5: 0.01 | U5: 0.24 | V5: 0 | W5: 0.01 | X5: 0.03 | Y5: 0 | Z5: 0.03 | AA5: 0.01
A6: =A5+12 -> 48 | B6: 26-30 | C6: {=ROUND(TRANSPOSE(INDIRECT("output!L"&$A6+2&":L"&$A6+13)),2)} -> -0.46 | D6: 0.58 | E6: 0.48 | F6: 4.02 | G6: 1.31 | H6: -0.01 | I6: 4.65 | J6: 0.39 | K6: -0.11 | L6: 0 | M6: -0.11 | N6: -0.09 | P6: {=ROUND(TRANSPOSE(INDIRECT("output!K"&$A6+2&":K"&$A6+13)),2)} -> 0.14 | Q6: 0.12 | R6: 0.11 | S6: 0 | T6: 0.02 | U6: 0.77 | V6: 0 | W6: 0.08 | X6: 0.51 | Y6: 0 | Z6: 0.51 | AA6: 0.57
A7: =A6+12 -> 60 | B7: 28-32 | C7: {=ROUND(TRANSPOSE(INDIRECT("output!L"&$A7+2&":L"&$A7+13)),2)} -> 0 | D7: 0.55 | E7: 0.82 | F7: 6.58 | G7: 1.87 | H7: 0 | I7: 5.55 | J7: 0.52 | K7: -0.07 | L7: 0 | M7: -0.07 | N7: -0.04 | P7: {=ROUND(TRANSPOSE(INDIRECT("output!K"&$A7+2&":K"&$A7+13)),2)} -> 0.9 | Q7: 0.12 | R7: 0.04 | S7: 0 | T7: 0.01 | U7: 0.99 | V7: 0 | W7: 0.07 | X7: 0.55 | Y7: 0 | Z7: 0.55 | AA7: 0.63
A8: =A7+12 -> 72 | B8: 30-34 | C8: {=ROUND(TRANSPOSE(INDIRECT("output!L"&$A8+2&":L"&$A8+13)),2)} -> 0.03 | D8: 0.85 | E8: 1.46 | F8: 6.99 | G8: 2.57 | H8: 0 | I8: 5.92 | J8: 1.08 | K8: 0.15 | L8: 0 | M8: 0.15 | N8: 0.53 | P8: {=ROUND(TRANSPOSE(INDIRECT("output!K"&$A8+2&":K"&$A8+13)),2)} -> 0.65 | Q8: 0.06 | R8: 0.02 | S8: 0 | T8: 0 | U8: 0.86 | V8: 0 | W8: 0.02 | X8: 0.2 | Y8: 0 | Z8: 0.2 | AA8: 0.04
A9: =A8+12 -> 84 | B9: 32-36 | C9: {=ROUND(TRANSPOSE(INDIRECT("output!L"&$A9+2&":L"&$A9+13)),2)} -> -0.24 | D9: 0.1 | E9: 1.58 | F9: 0.51 | G9: 0.83 | H9: 0.08 | I9: 0.79 | J9: 0.17 | K9: 0.27 | L9: 0 | M9: 0.27 | N9: 0.64 | P9: {=ROUND(TRANSPOSE(INDIRECT("output!K"&$A9+2&":K"&$A9+13)),2)} -> 0.28 | Q9: 0.44 | R9: 0.02 | S9: 0.15 | T9: 0.06 | U9: 0.52 | V9: 0.08 | W9: 0.3 | X9: 0.12 | Y9: 0 | Z9: 0.12 | AA9: 0.03
A10: =A9+12 -> 96 | B10: 34-38 | C10: {=ROUND(TRANSPOSE(INDIRECT("output!L"&$A10+2&":L"&$A10+13)),2)} -> 0.34 | D10: 0.6 | E10: 2.06 | F10: 0.28 | G10: 1.26 | H10: -0.01 | I10: 1.09 | J10: 0.82 | K10: 0.06 | L10: -0.08 | M10: 0.09 | N10: 0.06 | P10: {=ROUND(TRANSPOSE(INDIRECT("output!K"&$A10+2&":K"&$A10+13)),2)} -> 0.2 | Q10: 0.08 | R10: 0.01 | S10: 0.23 | T10: 0.02 | U10: 0.77 | V10: 0.04 | W10: 0.03 | X10: 0.45 | Y10: 0.31 | Z10: 0.37 | AA10: 0.52
A11: =A10+12 -> 108 | B11: 36-40 | C11: {=ROUND(TRANSPOSE(INDIRECT("output!L"&$A11+2&":L"&$A11+13)),2)} -> -0.01 | D11: 0.74 | E11: 1.35 | F11: 0.14 | G11: 0.93 | H11: -0.05 | I11: 0.73 | J11: 0.68 | K11: 0.03 | L11: -0.12 | M11: 0.08 | N11: 0 | P11: {=ROUND(TRANSPOSE(INDIRECT("output!K"&$A11+2&":K"&$A11+13)),2)} -> 0.82 | Q11: 0.06 | R11: 0.02 | S11: 0.4 | T11: 0.04 | U11: 0.57 | V11: 0.09 | W11: 0.05 | X11: 0.6 | Y11: 0.21 | Z11: 0.42 | AA11: 0.94
A12: =A11+12 -> 120 | B12: 38-42 | C12: {=ROUND(TRANSPOSE(INDIRECT("output!L"&$A12+2&":L"&$A12+13)),2)} -> -0.13 | D12: 0.47 | E12: 1.38 | F12: 2.36 | G12: 1.71 | H12: 0.07 | I12: 6.11 | J12: 6.37 | K12: 0 | L12: -0.14 | M12: 0.03 | N12: 0 | P12: {=ROUND(TRANSPOSE(INDIRECT("output!K"&$A12+2&":K"&$A12+13)),2)} -> 0.41 | Q12: 0.12 | R12: 0.02 | S12: 0 | T12: 0.01 | U12: 0.51 | V12: 0 | W12: 0 | X12: 0.93 | Y12: 0.22 | Z12: 0.65 | AA12: 0.92
A13: =A12+12 -> 132 | B13: 40-44 | C13: {=ROUND(TRANSPOSE(INDIRECT("output!L"&$A13+2&":L"&$A13+13)),2)} -> 0.05 | D13: 0.71 | E13: 1.23 | F13: 10.91 | G13: 2.18 | H13: 0.06 | I13: 14.58 | J13: 4.57 | K13: -0.39 | L13: -22.42 | M13: -0.25 | N13: -0.37 | P13: {=ROUND(TRANSPOSE(INDIRECT("output!K"&$A13+2&":K"&$A13+13)),2)} -> 0.53 | Q13: 0.08 | R13: 0.03 | S13: 0 | T13: 0.01 | U13: 0.53 | V13: 0 | W13: 0 | X13: 0.27 | Y13: 0 | Z13: 0.33 | AA13: 0.27
A14: =A13+12 -> 144 | B14: 42-46 | C14: {=ROUND(TRANSPOSE(INDIRECT("output!L"&$A14+2&":L"&$A14+13)),2)} -> -0.21 | D14: 0.55 | E14: 2.49 | F14: 11.18 | G14: 3.05 | H14: 0.13 | I14: 12.97 | J14: 4.05 | K14: -0.18 | L14: -0.17 | M14: -0.02 | N14: -0.19 | P14: {=ROUND(TRANSPOSE(INDIRECT("output!K"&$A14+2&":K"&$A14+13)),2)} -> 0.3 | Q14: 0.12 | R14: 0 | S14: 0 | T14: 0 | U14: 0.41 | V14: 0 | W14: 0 | X14: 0.44 | Y14: 0.17 | Z14: 0.73 | AA14: 0.36
... A27: =A26+12 -> 300 | B27: 68-72 | C27: {=ROUND(TRANSPOSE(INDIRECT("output!L"&$A27+2&":L"&$A27+13)),2)} -> -3.61 | D27: 0.04 | E27: 0 | F27: 1.01 | G27: 0.12 | H27: 0.26 | I27: 0.36 | J27: 0.01 | K27: 0.08 | L27: -0.96 | M27: 2.03 | N27: -0.06 | P27: {=ROUND(TRANSPOSE(INDIRECT("output!K"&$A27+2&":K"&$A27+13)),2)} -> 0 | Q27: 0.67 | R27: 0.96 | S27: 0.05 | T27: 0.47 | U27: 0.3 | V27: 0.22 | W27: 0.86 | X27: 0.41 | Y27: 0.01 | Z27: 0 | AA27: 0.55

Sheet simple
A1: Group | B1: BVMT_t1 | C1: BVMT_t2 | D1: BVMT_t3 | E1: BVMT_delayed_recall | G1: BVMT_t1 | H1: BVMT_t2 | I1: BVMT_t3 | J1: BVMT_delayed_recall
A2: 18-22 | B2: =clean!D2 -> 2.07 | C2: =clean!E2 -> 1.61 | D2: =clean!F2 -> 3.44 | E2: =clean!I2 -> 6.14 | G2: =clean!Q2 -> 0.01 | H2: =clean!R2 -> 0.01 | I2: =clean!S2 -> 0 | J2: =clean!V2 -> 0
A3: 20-24 | B3: =clean!D3 -> 2.6 | C3: =clean!E3 -> 3.78 | D3: =clean!F3 -> 5.08 | E3: =clean!I3 -> 0.65 | G3: =clean!Q3 -> 0 | H3: =clean!R3 -> 0 | I3: =clean!S3 -> 0 | J3: =clean!V3 -> 0.08
A4: 22-26 | B4: =clean!D4 -> 1.61 | C4: =clean!E4 -> 2.27 | D4: =clean!F4 -> 2.86 | E4: =clean!I4 -> 0.71 | G4: =clean!Q4 -> 0.02 | H4: =clean!R4 -> 0 | I4: =clean!S4 -> 0 | J4: =clean!V4 -> 0.06
A5: 24-28 | B5: =clean!D5 -> 1.24 | C5: =clean!E5 -> 1.41 | D5: =clean!F5 -> 2.89 | E5: =clean!I5 -> 3.71 | G5: =clean!Q5 -> 0.04 | H5: =clean!R5 -> 0.01 | I5: =clean!S5 -> 0 | J5: =clean!V5 -> 0
A6: 26-30 | B6: =clean!D6 -> 0.58 | C6: =clean!E6 -> 0.48 | D6: =clean!F6 -> 4.02 | E6: =clean!I6 -> 4.65 | G6: =clean!Q6 -> 0.12 | H6: =clean!R6 -> 0.11 | I6: =clean!S6 -> 0 | J6: =clean!V6 -> 0
A7: 28-32 | B7: =clean!D7 -> 0.55 | C7: =clean!E7 -> 0.82 | D7: =clean!F7 -> 6.58 | E7: =clean!I7 -> 5.55 | G7: =clean!Q7 -> 0.12 | H7: =clean!R7 -> 0.04 | I7: =clean!S7 -> 0 | J7: =clean!V7 -> 0
A8: 30-34 | B8: =clean!D8 -> 0.85 | C8: =clean!E8 -> 1.46 | D8: =clean!F8 -> 6.99 | E8: =clean!I8 -> 5.92 | G8: =clean!Q8 -> 0.06 | H8: =clean!R8 -> 0.02 | I8: =clean!S8 -> 0 | J8: =clean!V8 -> 0
A9: 32-36 | B9: =clean!D9 -> 0.1 | C9: =clean!E9 -> 1.58 | D9: =clean!F9 -> 0.51 | E9: =clean!I9 -> 0.79 | G9: =clean!Q9 -> 0.44 | H9: =clean!R9 -> 0.02 | I9: =clean!S9 -> 0.15 | J9: =clean!V9 -> 0.08
A10: 34-38 | B10: =clean!D10 -> 0.6 | C10: =clean!E10 -> 2.06 | D10: =clean!F10 -> 0.28 | E10: =clean!I10 -> 1.09 | G10: =clean!Q10 -> 0.08 | H10: =clean!R10 -> 0.01 | I10: =clean!S10 -> 0.23 | J10: =clean!V10 -> 0.04
A11: 36-40 | B11: =clean!D11 -> 0.74 | C11: =clean!E11 -> 1.35 | D11: =clean!F11 -> 0.14 | E11: =clean!I11 -> 0.73 | G11: =clean!Q11 -> 0.06 | H11: =clean!R11 -> 0.02 | I11: =clean!S11 -> 0.4 | J11: =clean!V11 -> 0.09
A12: 38-42 | B12: =clean!D12 -> 0.47 | C12: =clean!E12 -> 1.38 | D12: =clean!F12 -> 2.36 | E12: =clean!I12 -> 6.11 | G12: =clean!Q12 -> 0.12 | H12: =clean!R12 -> 0.02 | I12: =clean!S12 -> 0 | J12: =clean!V12 -> 0
A13: 40-44 | B13: =clean!D13 -> 0.71 | C13: =clean!E13 -> 1.23 | D13: =clean!F13 -> 10.91 | E13: =clean!I13 -> 14.58 | G13: =clean!Q13 -> 0.08 | H13: =clean!R13 -> 0.03 | I13: =clean!S13 -> 0 | J13: =clean!V13 -> 0
... A27: 68-72 | B27: =clean!D27 -> 0.04 | C27: =clean!E27 -> 0 | D27: =clean!F27 -> 1.01 | E27: =clean!I27 -> 0.36 | G27: =clean!Q27 -> 0.67 | H27: =clean!R27 -> 0.96 | I27: =clean!S27 -> 0.05 | J27: =clean!V27 -> 0.22

Sheet Sheet3
B4: 18-22 | C4: 20-24 | D4: 22-26 | E4: 24-28 | F4: 26-30 | G4: 28-32 | H4: 30-34 | I4: 32-36 | J4: 34-38 | K4: 36-40 | L4: 38-42 | M4: 40-44 | N4: 42-46 | O4: 44-48 | P4: 46-50 | Q4: 48-52 | R4: 50-54 | S4: 52-56 | T4: 54-58 | U4: 56-60 | V4: 58-62 | W4: 60-64 | X4: 62-66 | Y4: 64-68 | Z4: 66-70 | AA4: 68-72
